Workbook
Name lst_Equipe: OFFSET(Listas!$A$4,0,0,COUNTA(Listas!$A$4:$A$60),1)
Name lst_Status: OFFSET(Listas!$B$4,0,0,COUNTA(Listas!$B$4:$B$30),1)
Name lst_Frentes: OFFSET(Listas!$C$4,0,0,COUNTA(Listas!$C$4:$C$60),1)
Name lst_Atividades: OFFSET(Listas!$D$4,0,0,MAX(1,COUNTIF(Listas!$D$4:$D$597,"?*")),1)

Sheet Leia-me
A1: Cronograma Petrobio: como usar este arquivo
A3: Abas
A4: Geral: cronograma oficial por frente e subfrente. Cada atividade tem um ID único (ex.: EC-012).
A5: Painel: contagem automática por pessoa, por status e por frente, com tarefas atrasadas.
A6: Abas individuais (uma por pessoa): cada um lista e atualiza as próprias tarefas.
A7: Listas: nomes da equipe, status e frentes usados nas listas suspensas.
A9: Como funciona a atualização automática
A10: 1. Na sua aba, escolha na coluna A a atividade da Geral à qual sua tarefa pertence (lista suspensa "ID · descrição").
A11: 2. Escreva sua tarefa na coluna E (ou deixe em branco se sua parte é a própria atividade) e escolha o status.
A12: 3. Na Geral, a atividade mostra automaticamente: quem está envolvido (Equipe), quantas tarefas individuais foram concluídas e o texto de cada uma (Detalhamento individual).
A13: 4. O status oficial da atividade na Geral (coluna I) continua sendo preenchido pela coordenação/ponto focal.
A15: Incluir uma atividade nova na Geral
... A33: Em pasta de rede (VPN) o Excel não permite edição simultânea: enquanto uma pessoa edita, as outras abrem como somente leitura.

Sheet Geral
A1: Cronograma Petrobio: visão geral por frente
A2: Preencha as colunas brancas. Colunas cinzas são automáticas (não digite nelas). Nova atividade: insira uma linha, copie a linha de cima (Ctrl+D) e crie um ID novo e único na coluna A. Datas em itálico foram estimadas a partir do Gantt antigo; confira.
S3: Início do Gantt: | T3: 46097
S5: Gantt semanal (agrupado: clique em "−/+" acima das colunas para recolher) | T5: =T6 | U5: =IF(MONTH(U6)<>MONTH(T6),U6,"") | V5: =IF(MONTH(V6)<>MONTH(U6),V6,"") | W5: =IF(MONTH(W6)<>MONTH(V6),W6,"") | X5: =IF(MONTH(X6)<>MONTH(W6),X6,"") | Y5: =IF(MONTH(Y6)<>MONTH(X6),Y6,"") | Z5: =IF(MONTH(Z6)<>MONTH(Y6),Z6,"") | AA5: =IF(MONTH(AA6)<>MONTH(Z6),AA6,"") | AB5: =IF(MONTH(AB6)<>MONTH(AA6),AB6,"") | ... BI5: =IF(MONTH(BI6)<>MONTH(BH6),BI6,"")
A6: ID | B6: Etapa | C6: Frente | D6: Subfrente | E6: Atividade | F6: Ponto focal | G6: Equipe (automático) | H6: Outros envolvidos | I6: Status | J6: Concluídas / tarefas individuais (automático) | K6: Data inicial | L6: Data final | M6: Início replanejado | N6: Fim replanejado | O6: Data de entrega | P6: Início vigente (automático) | Q6: Fim vigente (automático) | R6: Observações | S6: Detalhamento individual (automático) | T6: =T$3-WEEKDAY(T$3,3) | U6: =T6+7 | V6: =U6+7 | W6: =V6+7 | X6: =W6+7 | Y6: =X6+7 | Z6: =Y6+7 | AA6: =Z6+7 | AB6: =AA6+7 | ... BI6: =BH6+7
B7: Extra - Artigo | C7: 1. Elaboração do artigo sobre a caixa de ferramentas | E7: 1. Elaboração do artigo sobre a caixa de ferramentas | F7: Thaís | G7: =IF($A7="","",_xlfn.TEXTJOIN("; ",TRUE,IF(COUNTIF('Clarice'!$B$6:$B$300,$A7)>0,"Clarice",""),IF(COUNTIF('Luisa'!$B$6:$B$300,$A7)>0,"Luisa",""),IF(COUNTIF('Lui'!$B$6:$B$300,$A7)>0,"Lui",""),IF(COUNTIF('Thaís'!$B$6:$B$300,$A7)>0,"Thaís",""),IF(COUNTIF('Daniel'!$B$6:$B$300,$A7)>0,"Daniel",""),IF(COUNTIF('Fernando'!$B$6:$B$300,$A7)>0,"Fernando",""),IF(COUNTIF('Stephanie'!$B$6:$B$300,$A7)>0,"Stephanie",""),IF(COUNTIF('Fox'!$B$6:$B$300,$A7)>0,"Fox",""),IF(COUNTIF('Bruna'!$B$6:$B$300,$A7)>0,"Bruna",""),IF(COUNTIF('Stella'!$B$6:$B$300,$A7)>0,"Stella",""),IF(COUNTIF('Igor'!$B$6:$B$300,$A7)>0,"Igor",""))) | J7: =IF(OR($A7="",(COUNTIF('Clarice'!$B$6:$B$300,$A7)+COUNTIF('Luisa'!$B$6:$B$300,$A7)+COUNTIF('Lui'!$B$6:$B$300,$A7)+COUNTIF('Thaís'!$B$6:$B$300,$A7)+COUNTIF('Daniel'!$B$6:$B$300,$A7)+COUNTIF('Fernando'!$B$6:$B$300,$A7)+COUNTIF('Stephanie'!$B$6:$B$300,$A7)+COUNTIF('Fox'!$B$6:$B$300,$A7)+COUNTIF('Bruna'!$B$6:$B$300,$A7)+COUNTIF('Stella'!$B$6:$B$300,$A7)+COUNTIF('Igor'!$B$6:$B$300,$A7))=0),"",(COUNTIFS('Clarice'!$B$6:$B$300,$A7,'Clarice'!$F$6:$F$300,"Concluído")+COUNTIFS('Luisa'!$B$6:$B$300,$A7,'Luisa'!$F$6:$F$300,"Concluído")+COUNTIFS('Lui'!$B$6:$B$300,$A7,'Lui'!$F$6:$F$300,"Concluído")+COUNTIFS('Thaís'!$B$6:$B$300,$A7,'Thaís'!$F$6:$F$300,"Concluído")+COUNTIFS('Daniel'!$B$6:$B$300,$A7,'Daniel'!$F$6:$F$300,"Concluído")+COUNTIFS('Fernando'!$B$6:$B$300,$A7,'Fernando'!$F$6:$F$300,"Concluído")+COUNTIFS('Stephanie'!$B$6:$B$300,$A7,'Stephanie'!$F$6:$F$300,"Concluído")+COUNTIFS('Fox'!$B$6:$B$300,$A7,'Fox'!$F$6:$F$300,"Concluído")+COUNTIFS('Bruna'!$B$6:$B$300,$A7,'Bruna'!$F$6:$F$300,"Concluído")+COUNTIFS('Stella'!$B$6:$B$300,$A7,'Stella'!$F$6:$F$300,"Concluído")+COUNTIFS('Igor'!$B$6:$B$300,$A7,'Igor'!$F$6:$F$300,"Concluído"))&" / "&(COUNTIF('Clarice'!$B$6:$B$300,$A7)+COUNTIF('Luisa'!$B$6:$B$300,$A7)+COUNTIF('Lui'!$B$6:$B$300,$A7)+COUNTIF('Thaís'!$B$6:$B$300,$A7)+COUNTIF('Daniel'!$B$6:$B$300,$A7)+COUNTIF('Fernando'!$B$6:$B$300,$A7)+COUNTIF('Stephanie'!$B$6:$B$300,$A7)+COUNTIF('Fox'!$B$6:$B$300,$A7)+COUNTIF('Bruna'!$B$6:$B$300,$A7)+COUNTIF('Stella'!$B$6:$B$300,$A7)+COUNTIF('Igor'!$B$6:$B$300,$A7))) | P7: =IF($A7="","",IF(M7<>"",M7,IF(K7<>"",K7,""))) | Q7: =IF($A7="","",IF(N7<>"",N7,IF(L7<>"",L7,""))) | S7: {=IF($A7="","",_xlfn.TEXTJOIN(CHAR(10),TRUE,IF('Clarice'!$B$6:$B$300=$A7,"Clarice"&IF('Clarice'!$E$6:$E$300="",""," : "&'Clarice'!$E$6:$E$300)&" ["&'Clarice'!$F$6:$F$300&"]",""),IF('Luisa'!$B$6:$B$300=$A7,"Luisa"&IF('Luisa'!$E$6:$E$300="",""," : "&'Luisa'!$E$6:$E$300)&" ["&'Luisa'!$F$6:$F$300&"]",""),IF('Lui'!$B$6:$B$300=$A7,"Lui"&IF('Lui'!$E$6:$E$300="",""," : "&'Lui'!$E$6:$E$300)&" ["&'Lui'!$F$6:$F$300&"]",""),IF('Thaís'!$B$6:$B$300=$A7,"Thaís"&IF('Thaís'!$E$6:$E$300="",""," : "&'Thaís'!$E$6:$E$300)&" ["&'Thaís'!$F$6:$F$300&"]",""),IF('Daniel'!$B$6:$B$300=$A7,"Daniel"&IF('Daniel'!$E$6:$E$300="",""," : "&'Daniel'!$E$6:$E$300)&" ["&'Daniel'!$F$6:$F$300&"]",""),IF('Fernando'!$B$6:$B$300=$A7,"Fernando"&IF('Fernando'!$E$6:$E$300="",""," : "&'Fernando'!$E$6:$E$300)&" ["&'Fernando'!$F$6:$F$300&"]",""),IF('Stephanie'!$B$6:$B$300=$A7,"Stephanie"&IF('Stephanie'!$E$6:$E$300="",""," : "&'Stephanie'!$E$6:$E$300)&" ["&'Stephanie'!$F$6:$F$300&"]",""),IF('Fox'!$B$6:$B$300=$A7,"Fox"&IF('Fox'!$E$6:$E$300="",""," : "&'Fox'!$E$6:$E$300)&" ["&'Fox'!$F$6:$F$300&"]",""),IF('Bruna'!$B$6:$B$300=$A7,"Bruna"&IF('Bruna'!$E$6:$E$300="",""," : "&'Bruna'!$E$6:$E$300)&" ["&'Bruna'!$F$6:$F$300&"]",""),IF('Stella'!$B$6:$B$300=$A7,"Stella"&IF('Stella'!$E$6:$E$300="",""," : "&'Stella'!$E$6:$E$300)&" ["&'Stella'!$F$6:$F$300&"]",""),IF('Igor'!$B$6:$B$300=$A7,"Igor"&IF('Igor'!$E$6:$E$300="",""," : "&'Igor'!$E$6:$E$300)&" ["&'Igor'!$F$6:$F$300&"]","")))}
A8: ART-001 | B8: Extra - Artigo | C8: 1. Elaboração do artigo sobre a caixa de ferramentas | E8: Definir o escopo do artigo | F8: Thaís | G8: =IF($A8="","",_xlfn.TEXTJOIN("; ",TRUE,IF(COUNTIF('Clarice'!$B$6:$B$300,$A8)>0,"Clarice",""),IF(COUNTIF('Luisa'!$B$6:$B$300,$A8)>0,"Luisa",""),IF(COUNTIF('Lui'!$B$6:$B$300,$A8)>0,"Lui",""),IF(COUNTIF('Thaís'!$B$6:$B$300,$A8)>0,"Thaís",""),IF(COUNTIF('Daniel'!$B$6:$B$300,$A8)>0,"Daniel",""),IF(COUNTIF('Fernando'!$B$6:$B$300,$A8)>0,"Fernando",""),IF(COUNTIF('Stephanie'!$B$6:$B$300,$A8)>0,"Stephanie",""),IF(COUNTIF('Fox'!$B$6:$B$300,$A8)>0,"Fox",""),IF(COUNTIF('Bruna'!$B$6:$B$300,$A8)>0,"Bruna",""),IF(COUNTIF('Stella'!$B$6:$B$300,$A8)>0,"Stella",""),IF(COUNTIF('Igor'!$B$6:$B$300,$A8)>0,"Igor",""))) | I8: Concluído | J8: =IF(OR($A8="",(COUNTIF('Clarice'!$B$6:$B$300,$A8)+COUNTIF('Luisa'!$B$6:$B$300,$A8)+COUNTIF('Lui'!$B$6:$B$300,$A8)+COUNTIF('Thaís'!$B$6:$B$300,$A8)+COUNTIF('Daniel'!$B$6:$B$300,$A8)+COUNTIF('Fernando'!$B$6:$B$300,$A8)+COUNTIF('Stephanie'!$B$6:$B$300,$A8)+COUNTIF('Fox'!$B$6:$B$300,$A8)+COUNTIF('Bruna'!$B$6:$B$300,$A8)+COUNTIF('Stella'!$B$6:$B$300,$A8)+COUNTIF('Igor'!$B$6:$B$300,$A8))=0),"",(COUNTIFS('Clarice'!$B$6:$B$300,$A8,'Clarice'!$F$6:$F$300,"Concluído")+COUNTIFS('Luisa'!$B$6:$B$300,$A8,'Luisa'!$F$6:$F$300,"Concluído")+COUNTIFS('Lui'!$B$6:$B$300,$A8,'Lui'!$F$6:$F$300,"Concluído")+COUNTIFS('Thaís'!$B$6:$B$300,$A8,'Thaís'!$F$6:$F$300,"Concluído")+COUNTIFS('Daniel'!$B$6:$B$300,$A8,'Daniel'!$F$6:$F$300,"Concluído")+COUNTIFS('Fernando'!$B$6:$B$300,$A8,'Fernando'!$F$6:$F$300,"Concluído")+COUNTIFS('Stephanie'!$B$6:$B$300,$A8,'Stephanie'!$F$6:$F$300,"Concluído")+COUNTIFS('Fox'!$B$6:$B$300,$A8,'Fox'!$F$6:$F$300,"Concluído")+COUNTIFS('Bruna'!$B$6:$B$300,$A8,'Bruna'!$F$6:$F$300,"Concluído")+COUNTIFS('Stella'!$B$6:$B$300,$A8,'Stella'!$F$6:$F$300,"Concluído")+COUNTIFS('Igor'!$B$6:$B$300,$A8,'Igor'!$F$6:$F$300,"Concluído"))&" / "&(COUNTIF('Clarice'!$B$6:$B$300,$A8)+COUNTIF('Luisa'!$B$6:$B$300,$A8)+COUNTIF('Lui'!$B$6:$B$300,$A8)+COUNTIF('Thaís'!$B$6:$B$300,$A8)+COUNTIF('Daniel'!$B$6:$B$300,$A8)+COUNTIF('Fernando'!$B$6:$B$300,$A8)+COUNTIF('Stephanie'!$B$6:$B$300,$A8)+COUNTIF('Fox'!$B$6:$B$300,$A8)+COUNTIF('Bruna'!$B$6:$B$300,$A8)+COUNTIF('Stella'!$B$6:$B$300,$A8)+COUNTIF('Igor'!$B$6:$B$300,$A8))) | K8: 46097 | L8: 46101 | P8: =IF($A8="","",IF(M8<>"",M8,IF(K8<>"",K8,""))) | Q8: =IF($A8="","",IF(N8<>"",N8,IF(L8<>"",L8,""))) | R8: [Original: "Toda a equipe"] | S8: {=IF($A8="","",_xlfn.TEXTJOIN(CHAR(10),TRUE,IF('Clarice'!$B$6:$B$300=$A8,"Clarice"&IF('Clarice'!$E$6:$E$300="",""," : "&'Clarice'!$E$6:$E$300)&" ["&'Clarice'!$F$6:$F$300&"]",""),IF('Luisa'!$B$6:$B$300=$A8,"Luisa"&IF('Luisa'!$E$6:$E$300="",""," : "&'Luisa'!$E$6:$E$300)&" ["&'Luisa'!$F$6:$F$300&"]",""),IF('Lui'!$B$6:$B$300=$A8,"Lui"&IF('Lui'!$E$6:$E$300="",""," : "&'Lui'!$E$6:$E$300)&" ["&'Lui'!$F$6:$F$300&"]",""),IF('Thaís'!$B$6:$B$300=$A8,"Thaís"&IF('Thaís'!$E$6:$E$300="",""," : "&'Thaís'!$E$6:$E$300)&" ["&'Thaís'!$F$6:$F$300&"]",""),IF('Daniel'!$B$6:$B$300=$A8,"Daniel"&IF('Daniel'!$E$6:$E$300="",""," : "&'Daniel'!$E$6:$E$300)&" ["&'Daniel'!$F$6:$F$300&"]",""),IF('Fernando'!$B$6:$B$300=$A8,"Fernando"&IF('Fernando'!$E$6:$E$300="",""," : "&'Fernando'!$E$6:$E$300)&" ["&'Fernando'!$F$6:$F$300&"]",""),IF('Stephanie'!$B$6:$B$300=$A8,"Stephanie"&IF('Stephanie'!$E$6:$E$300="",""," : "&'Stephanie'!$E$6:$E$300)&" ["&'Stephanie'!$F$6:$F$300&"]",""),IF('Fox'!$B$6:$B$300=$A8,"Fox"&IF('Fox'!$E$6:$E$300="",""," : "&'Fox'!$E$6:$E$300)&" ["&'Fox'!$F$6:$F$300&"]",""),IF('Bruna'!$B$6:$B$300=$A8,"Bruna"&IF('Bruna'!$E$6:$E$300="",""," : "&'Bruna'!$E$6:$E$300)&" ["&'Bruna'!$F$6:$F$300&"]",""),IF('Stella'!$B$6:$B$300=$A8,"Stella"&IF('Stella'!$E$6:$E$300="",""," : "&'Stella'!$E$6:$E$300)&" ["&'Stella'!$F$6:$F$300&"]",""),IF('Igor'!$B$6:$B$300=$A8,"Igor"&IF('Igor'!$E$6:$E$300="",""," : "&'Igor'!$E$6:$E$300)&" ["&'Igor'!$F$6:$F$300&"]","")))}
A9: ART-002 | B9: Extra - Artigo | C9: 1. Elaboração do artigo sobre a caixa de ferramentas | E9: Alinhar com a Petrobras o escopo do artigo | F9: Thaís | G9: =IF($A9="","",_xlfn.TEXTJOIN("; ",TRUE,IF(COUNTIF('Clarice'!$B$6:$B$300,$A9)>0,"Clarice",""),IF(COUNTIF('Luisa'!$B$6:$B$300,$A9)>0,"Luisa",""),IF(COUNTIF('Lui'!$B$6:$B$300,$A9)>0,"Lui",""),IF(COUNTIF('Thaís'!$B$6:$B$300,$A9)>0,"Thaís",""),IF(COUNTIF('Daniel'!$B$6:$B$300,$A9)>0,"Daniel",""),IF(COUNTIF('Fernando'!$B$6:$B$300,$A9)>0,"Fernando",""),IF(COUNTIF('Stephanie'!$B$6:$B$300,$A9)>0,"Stephanie",""),IF(COUNTIF('Fox'!$B$6:$B$300,$A9)>0,"Fox",""),IF(COUNTIF('Bruna'!$B$6:$B$300,$A9)>0,"Bruna",""),IF(COUNTIF('Stella'!$B$6:$B$300,$A9)>0,"Stella",""),IF(COUNTIF('Igor'!$B$6:$B$300,$A9)>0,"Igor",""))) | I9: Concluído | J9: =IF(OR($A9="",(COUNTIF('Clarice'!$B$6:$B$300,$A9)+COUNTIF('Luisa'!$B$6:$B$300,$A9)+COUNTIF('Lui'!$B$6:$B$300,$A9)+COUNTIF('Thaís'!$B$6:$B$300,$A9)+COUNTIF('Daniel'!$B$6:$B$300,$A9)+COUNTIF('Fernando'!$B$6:$B$300,$A9)+COUNTIF('Stephanie'!$B$6:$B$300,$A9)+COUNTIF('Fox'!$B$6:$B$300,$A9)+COUNTIF('Bruna'!$B$6:$B$300,$A9)+COUNTIF('Stella'!$B$6:$B$300,$A9)+COUNTIF('Igor'!$B$6:$B$300,$A9))=0),"",(COUNTIFS('Clarice'!$B$6:$B$300,$A9,'Clarice'!$F$6:$F$300,"Concluído")+COUNTIFS('Luisa'!$B$6:$B$300,$A9,'Luisa'!$F$6:$F$300,"Concluído")+COUNTIFS('Lui'!$B$6:$B$300,$A9,'Lui'!$F$6:$F$300,"Concluído")+COUNTIFS('Thaís'!$B$6:$B$300,$A9,'Thaís'!$F$6:$F$300,"Concluído")+COUNTIFS('Daniel'!$B$6:$B$300,$A9,'Daniel'!$F$6:$F$300,"Concluído")+COUNTIFS('Fernando'!$B$6:$B$300,$A9,'Fernando'!$F$6:$F$300,"Concluído")+COUNTIFS('Stephanie'!$B$6:$B$300,$A9,'Stephanie'!$F$6:$F$300,"Concluído")+COUNTIFS('Fox'!$B$6:$B$300,$A9,'Fox'!$F$6:$F$300,"Concluído")+COUNTIFS('Bruna'!$B$6:$B$300,$A9,'Bruna'!$F$6:$F$300,"Concluído")+COUNTIFS('Stella'!$B$6:$B$300,$A9,'Stella'!$F$6:$F$300,"Concluído")+COUNTIFS('Igor'!$B$6:$B$300,$A9,'Igor'!$F$6:$F$300,"Concluído"))&" / "&(COUNTIF('Clarice'!$B$6:$B$300,$A9)+COUNTIF('Luisa'!$B$6:$B$300,$A9)+COUNTIF('Lui'!$B$6:$B$300,$A9)+COUNTIF('Thaís'!$B$6:$B$300,$A9)+COUNTIF('Daniel'!$B$6:$B$300,$A9)+COUNTIF('Fernando'!$B$6:$B$300,$A9)+COUNTIF('Stephanie'!$B$6:$B$300,$A9)+COUNTIF('Fox'!$B$6:$B$300,$A9)+COUNTIF('Bruna'!$B$6:$B$300,$A9)+COUNTIF('Stella'!$B$6:$B$300,$A9)+COUNTIF('Igor'!$B$6:$B$300,$A9))) | K9: 46097 | L9: 46101 | P9: =IF($A9="","",IF(M9<>"",M9,IF(K9<>"",K9,""))) | Q9: =IF($A9="","",IF(N9<>"",N9,IF(L9<>"",L9,""))) | S9: {=IF($A9="","",_xlfn.TEXTJOIN(CHAR(10),TRUE,IF('Clarice'!$B$6:$B$300=$A9,"Clarice"&IF('Clarice'!$E$6:$E$300="",""," : "&'Clarice'!$E$6:$E$300)&" ["&'Clarice'!$F$6:$F$300&"]",""),IF('Luisa'!$B$6:$B$300=$A9,"Luisa"&IF('Luisa'!$E$6:$E$300="",""," : "&'Luisa'!$E$6:$E$300)&" ["&'Luisa'!$F$6:$F$300&"]",""),IF('Lui'!$B$6:$B$300=$A9,"Lui"&IF('Lui'!$E$6:$E$300="",""," : "&'Lui'!$E$6:$E$300)&" ["&'Lui'!$F$6:$F$300&"]",""),IF('Thaís'!$B$6:$B$300=$A9,"Thaís"&IF('Thaís'!$E$6:$E$300="",""," : "&'Thaís'!$E$6:$E$300)&" ["&'Thaís'!$F$6:$F$300&"]",""),IF('Daniel'!$B$6:$B$300=$A9,"Daniel"&IF('Daniel'!$E$6:$E$300="",""," : "&'Daniel'!$E$6:$E$300)&" ["&'Daniel'!$F$6:$F$300&"]",""),IF('Fernando'!$B$6:$B$300=$A9,"Fernando"&IF('Fernando'!$E$6:$E$300="",""," : "&'Fernando'!$E$6:$E$300)&" ["&'Fernando'!$F$6:$F$300&"]",""),IF('Stephanie'!$B$6:$B$300=$A9,"Stephanie"&IF('Stephanie'!$E$6:$E$300="",""," : "&'Stephanie'!$E$6:$E$300)&" ["&'Stephanie'!$F$6:$F$300&"]",""),IF('Fox'!$B$6:$B$300=$A9,"Fox"&IF('Fox'!$E$6:$E$300="",""," : "&'Fox'!$E$6:$E$300)&" ["&'Fox'!$F$6:$F$300&"]",""),IF('Bruna'!$B$6:$B$300=$A9,"Bruna"&IF('Bruna'!$E$6:$E$300="",""," : "&'Bruna'!$E$6:$E$300)&" ["&'Bruna'!$F$6:$F$300&"]",""),IF('Stella'!$B$6:$B$300=$A9,"Stella"&IF('Stella'!$E$6:$E$300="",""," : "&'Stella'!$E$6:$E$300)&" ["&'Stella'!$F$6:$F$300&"]",""),IF('Igor'!$B$6:$B$300=$A9,"Igor"&IF('Igor'!$E$6:$E$300="",""," : "&'Igor'!$E$6:$E$300)&" ["&'Igor'!$F$6:$F$300&"]","")))}
A10: ART-003 | B10: Extra - Artigo | C10: 1. Elaboração do artigo sobre a caixa de ferramentas | E10: Escrever a versão preliminar | F10: Thaís | G10: =IF($A10="","",_xlfn.TEXTJOIN("; ",TRUE,IF(COUNTIF('Clarice'!$B$6:$B$300,$A10)>0,"Clarice",""),IF(COUNTIF('Luisa'!$B$6:$B$300,$A10)>0,"Luisa",""),IF(COUNTIF('Lui'!$B$6:$B$300,$A10)>0,"Lui",""),IF(COUNTIF('Thaís'!$B$6:$B$300,$A10)>0,"Thaís",""),IF(COUNTIF('Daniel'!$B$6:$B$300,$A10)>0,"Daniel",""),IF(COUNTIF('Fernando'!$B$6:$B$300,$A10)>0,"Fernando",""),IF(COUNTIF('Stephanie'!$B$6:$B$300,$A10)>0,"Stephanie",""),IF(COUNTIF('Fox'!$B$6:$B$300,$A10)>0,"Fox",""),IF(COUNTIF('Bruna'!$B$6:$B$300,$A10)>0,"Bruna",""),IF(COUNTIF('Stella'!$B$6:$B$300,$A10)>0,"Stella",""),IF(COUNTIF('Igor'!$B$6:$B$300,$A10)>0,"Igor",""))) | I10: Concluído | J10: =IF(OR($A10="",(COUNTIF('Clarice'!$B$6:$B$300,$A10)+COUNTIF('Luisa'!$B$6:$B$300,$A10)+COUNTIF('Lui'!$B$6:$B$300,$A10)+COUNTIF('Thaís'!$B$6:$B$300,$A10)+COUNTIF('Daniel'!$B$6:$B$300,$A10)+COUNTIF('Fernando'!$B$6:$B$300,$A10)+COUNTIF('Stephanie'!$B$6:$B$300,$A10)+COUNTIF('Fox'!$B$6:$B$300,$A10)+COUNTIF('Bruna'!$B$6:$B$300,$A10)+COUNTIF('Stella'!$B$6:$B$300,$A10)+COUNTIF('Igor'!$B$6:$B$300,$A10))=0),"",(COUNTIFS('Clarice'!$B$6:$B$300,$A10,'Clarice'!$F$6:$F$300,"Concluído")+COUNTIFS('Luisa'!$B$6:$B$300,$A10,'Luisa'!$F$6:$F$300,"Concluído")+COUNTIFS('Lui'!$B$6:$B$300,$A10,'Lui'!$F$6:$F$300,"Concluído")+COUNTIFS('Thaís'!$B$6:$B$300,$A10,'Thaís'!$F$6:$F$300,"Concluído")+COUNTIFS('Daniel'!$B$6:$B$300,$A10,'Daniel'!$F$6:$F$300,"Concluído")+COUNTIFS('Fernando'!$B$6:$B$300,$A10,'Fernando'!$F$6:$F$300,"Concluído")+COUNTIFS('Stephanie'!$B$6:$B$300,$A10,'Stephanie'!$F$6:$F$300,"Concluído")+COUNTIFS('Fox'!$B$6:$B$300,$A10,'Fox'!$F$6:$F$300,"Concluído")+COUNTIFS('Bruna'!$B$6:$B$300,$A10,'Bruna'!$F$6:$F$300,"Concluído")+COUNTIFS('Stella'!$B$6:$B$300,$A10,'Stella'!$F$6:$F$300,"Concluído")+COUNTIFS('Igor'!$B$6:$B$300,$A10,'Igor'!$F$6:$F$300,"Concluído"))&" / "&(COUNTIF('Clarice'!$B$6:$B$300,$A10)+COUNTIF('Luisa'!$B$6:$B$300,$A10)+COUNTIF('Lui'!$B$6:$B$300,$A10)+COUNTIF('Thaís'!$B$6:$B$300,$A10)+COUNTIF('Daniel'!$B$6:$B$300,$A10)+COUNTIF('Fernando'!$B$6:$B$300,$A10)+COUNTIF('Stephanie'!$B$6:$B$300,$A10)+COUNTIF('Fox'!$B$6:$B$300,$A10)+COUNTIF('Bruna'!$B$6:$B$300,$A10)+COUNTIF('Stella'!$B$6:$B$300,$A10)+COUNTIF('Igor'!$B$6:$B$300,$A10))) | K10: 46097 | L10: 46112 | P10: =IF($A10="","",IF(M10<>"",M10,IF(K10<>"",K10,""))) | Q10: =IF($A10="","",IF(N10<>"",N10,IF(L10<>"",L10,""))) | S10: {=IF($A10="","",_xlfn.TEXTJOIN(CHAR(10),TRUE,IF('Clarice'!$B$6:$B$300=$A10,"Clarice"&IF('Clarice'!$E$6:$E$300="",""," : "&'Clarice'!$E$6:$E$300)&" ["&'Clarice'!$F$6:$F$300&"]",""),IF('Luisa'!$B$6:$B$300=$A10,"Luisa"&IF('Luisa'!$E$6:$E$300="",""," : "&'Luisa'!$E$6:$E$300)&" ["&'Luisa'!$F$6:$F$300&"]",""),IF('Lui'!$B$6:$B$300=$A10,"Lui"&IF('Lui'!$E$6:$E$300="",""," : "&'Lui'!$E$6:$E$300)&" ["&'Lui'!$F$6:$F$300&"]",""),IF('Thaís'!$B$6:$B$300=$A10,"Thaís"&IF('Thaís'!$E$6:$E$300="",""," : "&'Thaís'!$E$6:$E$300)&" ["&'Thaís'!$F$6:$F$300&"]",""),IF('Daniel'!$B$6:$B$300=$A10,"Daniel"&IF('Daniel'!$E$6:$E$300="",""," : "&'Daniel'!$E$6:$E$300)&" ["&'Daniel'!$F$6:$F$300&"]",""),IF('Fernando'!$B$6:$B$300=$A10,"Fernando"&IF('Fernando'!$E$6:$E$300="",""," : "&'Fernando'!$E$6:$E$300)&" ["&'Fernando'!$F$6:$F$300&"]",""),IF('Stephanie'!$B$6:$B$300=$A10,"Stephanie"&IF('Stephanie'!$E$6:$E$300="",""," : "&'Stephanie'!$E$6:$E$300)&" ["&'Stephanie'!$F$6:$F$300&"]",""),IF('Fox'!$B$6:$B$300=$A10,"Fox"&IF('Fox'!$E$6:$E$300="",""," : "&'Fox'!$E$6:$E$300)&" ["&'Fox'!$F$6:$F$300&"]",""),IF('Bruna'!$B$6:$B$300=$A10,"Bruna"&IF('Bruna'!$E$6:$E$300="",""," : "&'Bruna'!$E$6:$E$300)&" ["&'Bruna'!$F$6:$F$300&"]",""),IF('Stella'!$B$6:$B$300=$A10,"Stella"&IF('Stella'!$E$6:$E$300="",""," : "&'Stella'!$E$6:$E$300)&" ["&'Stella'!$F$6:$F$300&"]",""),IF('Igor'!$B$6:$B$300=$A10,"Igor"&IF('Igor'!$E$6:$E$300="",""," : "&'Igor'!$E$6:$E$300)&" ["&'Igor'!$F$6:$F$300&"]","")))}
A11: ART-004 | B11: Extra - Artigo | C11: 1. Elaboração do artigo sobre a caixa de ferramentas | E11: Preparar tabelas e figuras | F11: Thaís | G11: =IF($A11="","",_xlfn.TEXTJOIN("; ",TRUE,IF(COUNTIF('Clarice'!$B$6:$B$300,$A11)>0,"Clarice",""),IF(COUNTIF('Luisa'!$B$6:$B$300,$A11)>0,"Luisa",""),IF(COUNTIF('Lui'!$B$6:$B$300,$A11)>0,"Lui",""),IF(COUNTIF('Thaís'!$B$6:$B$300,$A11)>0,"Thaís",""),IF(COUNTIF('Daniel'!$B$6:$B$300,$A11)>0,"Daniel",""),IF(COUNTIF('Fernando'!$B$6:$B$300,$A11)>0,"Fernando",""),IF(COUNTIF('Stephanie'!$B$6:$B$300,$A11)>0,"Stephanie",""),IF(COUNTIF('Fox'!$B$6:$B$300,$A11)>0,"Fox",""),IF(COUNTIF('Bruna'!$B$6:$B$300,$A11)>0,"Bruna",""),IF(COUNTIF('Stella'!$B$6:$B$300,$A11)>0,"Stella",""),IF(COUNTIF('Igor'!$B$6:$B$300,$A11)>0,"Igor",""))) | I11: Concluído | J11: =IF(OR($A11="",(COUNTIF('Clarice'!$B$6:$B$300,$A11)+COUNTIF('Luisa'!$B$6:$B$300,$A11)+COUNTIF('Lui'!$B$6:$B$300,$A11)+COUNTIF('Thaís'!$B$6:$B$300,$A11)+COUNTIF('Daniel'!$B$6:$B$300,$A11)+COUNTIF('Fernando'!$B$6:$B$300,$A11)+COUNTIF('Stephanie'!$B$6:$B$300,$A11)+COUNTIF('Fox'!$B$6:$B$300,$A11)+COUNTIF('Bruna'!$B$6:$B$300,$A11)+COUNTIF('Stella'!$B$6:$B$300,$A11)+COUNTIF('Igor'!$B$6:$B$300,$A11))=0),"",(COUNTIFS('Clarice'!$B$6:$B$300,$A11,'Clarice'!$F$6:$F$300,"Concluído")+COUNTIFS('Luisa'!$B$6:$B$300,$A11,'Luisa'!$F$6:$F$300,"Concluído")+COUNTIFS('Lui'!$B$6:$B$300,$A11,'Lui'!$F$6:$F$300,"Concluído")+COUNTIFS('Thaís'!$B$6:$B$300,$A11,'Thaís'!$F$6:$F$300,"Concluído")+COUNTIFS('Daniel'!$B$6:$B$300,$A11,'Daniel'!$F$6:$F$300,"Concluído")+COUNTIFS('Fernando'!$B$6:$B$300,$A11,'Fernando'!$F$6:$F$300,"Concluído")+COUNTIFS('Stephanie'!$B$6:$B$300,$A11,'Stephanie'!$F$6:$F$300,"Concluído")+COUNTIFS('Fox'!$B$6:$B$300,$A11,'Fox'!$F$6:$F$300,"Concluído")+COUNTIFS('Bruna'!$B$6:$B$300,$A11,'Bruna'!$F$6:$F$300,"Concluído")+COUNTIFS('Stella'!$B$6:$B$300,$A11,'Stella'!$F$6:$F$300,"Concluído")+COUNTIFS('Igor'!$B$6:$B$300,$A11,'Igor'!$F$6:$F$300,"Concluído"))&" / "&(COUNTIF('Clarice'!$B$6:$B$300,$A11)+COUNTIF('Luisa'!$B$6:$B$300,$A11)+COUNTIF('Lui'!$B$6:$B$300,$A11)+COUNTIF('Thaís'!$B$6:$B$300,$A11)+COUNTIF('Daniel'!$B$6:$B$300,$A11)+COUNTIF('Fernando'!$B$6:$B$300,$A11)+COUNTIF('Stephanie'!$B$6:$B$300,$A11)+COUNTIF('Fox'!$B$6:$B$300,$A11)+COUNTIF('Bruna'!$B$6:$B$300,$A11)+COUNTIF('Stella'!$B$6:$B$300,$A11)+COUNTIF('Igor'!$B$6:$B$300,$A11))) | K11: 46097 | L11: 46112 | M11: 46097 | N11: 46192 | P11: =IF($A11="","",IF(M11<>"",M11,IF(K11<>"",K11,""))) | Q11: =IF($A11="","",IF(N11<>"",N11,IF(L11<>"",L11,""))) | S11: {=IF($A11="","",_xlfn.TEXTJOIN(CHAR(10),TRUE,IF('Clarice'!$B$6:$B$300=$A11,"Clarice"&IF('Clarice'!$E$6:$E$300="",""," : "&'Clarice'!$E$6:$E$300)&" ["&'Clarice'!$F$6:$F$300&"]",""),IF('Luisa'!$B$6:$B$300=$A11,"Luisa"&IF('Luisa'!$E$6:$E$300="",""," : "&'Luisa'!$E$6:$E$300)&" ["&'Luisa'!$F$6:$F$300&"]",""),IF('Lui'!$B$6:$B$300=$A11,"Lui"&IF('Lui'!$E$6:$E$300="",""," : "&'Lui'!$E$6:$E$300)&" ["&'Lui'!$F$6:$F$300&"]",""),IF('Thaís'!$B$6:$B$300=$A11,"Thaís"&IF('Thaís'!$E$6:$E$300="",""," : "&'Thaís'!$E$6:$E$300)&" ["&'Thaís'!$F$6:$F$300&"]",""),IF('Daniel'!$B$6:$B$300=$A11,"Daniel"&IF('Daniel'!$E$6:$E$300="",""," : "&'Daniel'!$E$6:$E$300)&" ["&'Daniel'!$F$6:$F$300&"]",""),IF('Fernando'!$B$6:$B$300=$A11,"Fernando"&IF('Fernando'!$E$6:$E$300="",""," : "&'Fernando'!$E$6:$E$300)&" ["&'Fernando'!$F$6:$F$300&"]",""),IF('Stephanie'!$B$6:$B$300=$A11,"Stephanie"&IF('Stephanie'!$E$6:$E$300="",""," : "&'Stephanie'!$E$6:$E$300)&" ["&'Stephanie'!$F$6:$F$300&"]",""),IF('Fox'!$B$6:$B$300=$A11,"Fox"&IF('Fox'!$E$6:$E$300="",""," : "&'Fox'!$E$6:$E$300)&" ["&'Fox'!$F$6:$F$300&"]",""),IF('Bruna'!$B$6:$B$300=$A11,"Bruna"&IF('Bruna'!$E$6:$E$300="",""," : "&'Bruna'!$E$6:$E$300)&" ["&'Bruna'!$F$6:$F$300&"]",""),IF('Stella'!$B$6:$B$300=$A11,"Stella"&IF('Stella'!$E$6:$E$300="",""," : "&'Stella'!$E$6:$E$300)&" ["&'Stella'!$F$6:$F$300&"]",""),IF('Igor'!$B$6:$B$300=$A11,"Igor"&IF('Igor'!$E$6:$E$300="",""," : "&'Igor'!$E$6:$E$300)&" ["&'Igor'!$F$6:$F$300&"]","")))}
A12: ART-005 | B12: Extra - Artigo | C12: 1. Elaboração do artigo sobre a caixa de ferramentas | E12: Preparar material suplementar | F12: Thaís | G12: =IF($A12="","",_xlfn.TEXTJOIN("; ",TRUE,IF(COUNTIF('Clarice'!$B$6:$B$300,$A12)>0,"Clarice",""),IF(COUNTIF('Luisa'!$B$6:$B$300,$A12)>0,"Luisa",""),IF(COUNTIF('Lui'!$B$6:$B$300,$A12)>0,"Lui",""),IF(COUNTIF('Thaís'!$B$6:$B$300,$A12)>0,"Thaís",""),IF(COUNTIF('Daniel'!$B$6:$B$300,$A12)>0,"Daniel",""),IF(COUNTIF('Fernando'!$B$6:$B$300,$A12)>0,"Fernando",""),IF(COUNTIF('Stephanie'!$B$6:$B$300,$A12)>0,"Stephanie",""),IF(COUNTIF('Fox'!$B$6:$B$300,$A12)>0,"Fox",""),IF(COUNTIF('Bruna'!$B$6:$B$300,$A12)>0,"Bruna",""),IF(COUNTIF('Stella'!$B$6:$B$300,$A12)>0,"Stella",""),IF(COUNTIF('Igor'!$B$6:$B$300,$A12)>0,"Igor",""))) | I12: Concluído | J12: =IF(OR($A12="",(COUNTIF('Clarice'!$B$6:$B$300,$A12)+COUNTIF('Luisa'!$B$6:$B$300,$A12)+COUNTIF('Lui'!$B$6:$B$300,$A12)+COUNTIF('Thaís'!$B$6:$B$300,$A12)+COUNTIF('Daniel'!$B$6:$B$300,$A12)+COUNTIF('Fernando'!$B$6:$B$300,$A12)+COUNTIF('Stephanie'!$B$6:$B$300,$A12)+COUNTIF('Fox'!$B$6:$B$300,$A12)+COUNTIF('Bruna'!$B$6:$B$300,$A12)+COUNTIF('Stella'!$B$6:$B$300,$A12)+COUNTIF('Igor'!$B$6:$B$300,$A12))=0),"",(COUNTIFS('Clarice'!$B$6:$B$300,$A12,'Clarice'!$F$6:$F$300,"Concluído")+COUNTIFS('Luisa'!$B$6:$B$300,$A12,'Luisa'!$F$6:$F$300,"Concluído")+COUNTIFS('Lui'!$B$6:$B$300,$A12,'Lui'!$F$6:$F$300,"Concluído")+COUNTIFS('Thaís'!$B$6:$B$300,$A12,'Thaís'!$F$6:$F$300,"Concluído")+COUNTIFS('Daniel'!$B$6:$B$300,$A12,'Daniel'!$F$6:$F$300,"Concluído")+COUNTIFS('Fernando'!$B$6:$B$300,$A12,'Fernando'!$F$6:$F$300,"Concluído")+COUNTIFS('Stephanie'!$B$6:$B$300,$A12,'Stephanie'!$F$6:$F$300,"Concluído")+COUNTIFS('Fox'!$B$6:$B$300,$A12,'Fox'!$F$6:$F$300,"Concluído")+COUNTIFS('Bruna'!$B$6:$B$300,$A12,'Bruna'!$F$6:$F$300,"Concluído")+COUNTIFS('Stella'!$B$6:$B$300,$A12,'Stella'!$F$6:$F$300,"Concluído")+COUNTIFS('Igor'!$B$6:$B$300,$A12,'Igor'!$F$6:$F$300,"Concluído"))&" / "&(COUNTIF('Clarice'!$B$6:$B$300,$A12)+COUNTIF('Luisa'!$B$6:$B$300,$A12)+COUNTIF('Lui'!$B$6:$B$300,$A12)+COUNTIF('Thaís'!$B$6:$B$300,$A12)+COUNTIF('Daniel'!$B$6:$B$300,$A12)+COUNTIF('Fernando'!$B$6:$B$300,$A12)+COUNTIF('Stephanie'!$B$6:$B$300,$A12)+COUNTIF('Fox'!$B$6:$B$300,$A12)+COUNTIF('Bruna'!$B$6:$B$300,$A12)+COUNTIF('Stella'!$B$6:$B$300,$A12)+COUNTIF('Igor'!$B$6:$B$300,$A12))) | K12: 46097 | L12: 46114 | M12: 46097 | N12: 46185 | P12: =IF($A12="","",IF(M12<>"",M12,IF(K12<>"",K12,""))) | Q12: =IF($A12="","",IF(N12<>"",N12,IF(L12<>"",L12,""))) | S12: {=IF($A12="","",_xlfn.TEXTJOIN(CHAR(10),TRUE,IF('Clarice'!$B$6:$B$300=$A12,"Clarice"&IF('Clarice'!$E$6:$E$300="",""," : "&'Clarice'!$E$6:$E$300)&" ["&'Clarice'!$F$6:$F$300&"]",""),IF('Luisa'!$B$6:$B$300=$A12,"Luisa"&IF('Luisa'!$E$6:$E$300="",""," : "&'Luisa'!$E$6:$E$300)&" ["&'Luisa'!$F$6:$F$300&"]",""),IF('Lui'!$B$6:$B$300=$A12,"Lui"&IF('Lui'!$E$6:$E$300="",""," : "&'Lui'!$E$6:$E$300)&" ["&'Lui'!$F$6:$F$300&"]",""),IF('Thaís'!$B$6:$B$300=$A12,"Thaís"&IF('Thaís'!$E$6:$E$300="",""," : "&'Thaís'!$E$6:$E$300)&" ["&'Thaís'!$F$6:$F$300&"]",""),IF('Daniel'!$B$6:$B$300=$A12,"Daniel"&IF('Daniel'!$E$6:$E$300="",""," : "&'Daniel'!$E$6:$E$300)&" ["&'Daniel'!$F$6:$F$300&"]",""),IF('Fernando'!$B$6:$B$300=$A12,"Fernando"&IF('Fernando'!$E$6:$E$300="",""," : "&'Fernando'!$E$6:$E$300)&" ["&'Fernando'!$F$6:$F$300&"]",""),IF('Stephanie'!$B$6:$B$300=$A12,"Stephanie"&IF('Stephanie'!$E$6:$E$300="",""," : "&'Stephanie'!$E$6:$E$300)&" ["&'Stephanie'!$F$6:$F$300&"]",""),IF('Fox'!$B$6:$B$300=$A12,"Fox"&IF('Fox'!$E$6:$E$300="",""," : "&'Fox'!$E$6:$E$300)&" ["&'Fox'!$F$6:$F$300&"]",""),IF('Bruna'!$B$6:$B$300=$A12,"Bruna"&IF('Bruna'!$E$6:$E$300="",""," : "&'Bruna'!$E$6:$E$300)&" ["&'Bruna'!$F$6:$F$300&"]",""),IF('Stella'!$B$6:$B$300=$A12,"Stella"&IF('Stella'!$E$6:$E$300="",""," : "&'Stella'!$E$6:$E$300)&" ["&'Stella'!$F$6:$F$300&"]",""),IF('Igor'!$B$6:$B$300=$A12,"Igor"&IF('Igor'!$E$6:$E$300="",""," : "&'Igor'!$E$6:$E$300)&" ["&'Igor'!$F$6:$F$300&"]","")))}
A13: ART-006 | B13: Extra - Artigo | C13: 1. Elaboração do artigo sobre a caixa de ferramentas | E13: Revisão pela equipe interna | F13: Thaís | G13: =IF($A13="","",_xlfn.TEXTJOIN("; ",TRUE,IF(COUNTIF('Clarice'!$B$6:$B$300,$A13)>0,"Clarice",""),IF(COUNTIF('Luisa'!$B$6:$B$300,$A13)>0,"Luisa",""),IF(COUNTIF('Lui'!$B$6:$B$300,$A13)>0,"Lui",""),IF(COUNTIF('Thaís'!$B$6:$B$300,$A13)>0,"Thaís",""),IF(COUNTIF('Daniel'!$B$6:$B$300,$A13)>0,"Daniel",""),IF(COUNTIF('Fernando'!$B$6:$B$300,$A13)>0,"Fernando",""),IF(COUNTIF('Stephanie'!$B$6:$B$300,$A13)>0,"Stephanie",""),IF(COUNTIF('Fox'!$B$6:$B$300,$A13)>0,"Fox",""),IF(COUNTIF('Bruna'!$B$6:$B$300,$A13)>0,"Bruna",""),IF(COUNTIF('Stella'!$B$6:$B$300,$A13)>0,"Stella",""),IF(COUNTIF('Igor'!$B$6:$B$300,$A13)>0,"Igor",""))) | I13: Concluído | J13: =IF(OR($A13="",(COUNTIF('Clarice'!$B$6:$B$300,$A13)+COUNTIF('Luisa'!$B$6:$B$300,$A13)+COUNTIF('Lui'!$B$6:$B$300,$A13)+COUNTIF('Thaís'!$B$6:$B$300,$A13)+COUNTIF('Daniel'!$B$6:$B$300,$A13)+COUNTIF('Fernando'!$B$6:$B$300,$A13)+COUNTIF('Stephanie'!$B$6:$B$300,$A13)+COUNTIF('Fox'!$B$6:$B$300,$A13)+COUNTIF('Bruna'!$B$6:$B$300,$A13)+COUNTIF('Stella'!$B$6:$B$300,$A13)+COUNTIF('Igor'!$B$6:$B$300,$A13))=0),"",(COUNTIFS('Clarice'!$B$6:$B$300,$A13,'Clarice'!$F$6:$F$300,"Concluído")+COUNTIFS('Luisa'!$B$6:$B$300,$A13,'Luisa'!$F$6:$F$300,"Concluído")+COUNTIFS('Lui'!$B$6:$B$300,$A13,'Lui'!$F$6:$F$300,"Concluído")+COUNTIFS('Thaís'!$B$6:$B$300,$A13,'Thaís'!$F$6:$F$300,"Concluído")+COUNTIFS('Daniel'!$B$6:$B$300,$A13,'Daniel'!$F$6:$F$300,"Concluído")+COUNTIFS('Fernando'!$B$6:$B$300,$A13,'Fernando'!$F$6:$F$300,"Concluído")+COUNTIFS('Stephanie'!$B$6:$B$300,$A13,'Stephanie'!$F$6:$F$300,"Concluído")+COUNTIFS('Fox'!$B$6:$B$300,$A13,'Fox'!$F$6:$F$300,"Concluído")+COUNTIFS('Bruna'!$B$6:$B$300,$A13,'Bruna'!$F$6:$F$300,"Concluído")+COUNTIFS('Stella'!$B$6:$B$300,$A13,'Stella'!$F$6:$F$300,"Concluído")+COUNTIFS('Igor'!$B$6:$B$300,$A13,'Igor'!$F$6:$F$300,"Concluído"))&" / "&(COUNTIF('Clarice'!$B$6:$B$300,$A13)+COUNTIF('Luisa'!$B$6:$B$300,$A13)+COUNTIF('Lui'!$B$6:$B$300,$A13)+COUNTIF('Thaís'!$B$6:$B$300,$A13)+COUNTIF('Daniel'!$B$6:$B$300,$A13)+COUNTIF('Fernando'!$B$6:$B$300,$A13)+COUNTIF('Stephanie'!$B$6:$B$300,$A13)+COUNTIF('Fox'!$B$6:$B$300,$A13)+COUNTIF('Bruna'!$B$6:$B$300,$A13)+COUNTIF('Stella'!$B$6:$B$300,$A13)+COUNTIF('Igor'!$B$6:$B$300,$A13))) | K13: 46111 | L13: 46129 | P13: =IF($A13="","",IF(M13<>"",M13,IF(K13<>"",K13,""))) | Q13: =IF($A13="","",IF(N13<>"",N13,IF(L13<>"",L13,""))) | S13: {=IF($A13="","",_xlfn.TEXTJOIN(CHAR(10),TRUE,IF('Clarice'!$B$6:$B$300=$A13,"Clarice"&IF('Clarice'!$E$6:$E$300="",""," : "&'Clarice'!$E$6:$E$300)&" ["&'Clarice'!$F$6:$F$300&"]",""),IF('Luisa'!$B$6:$B$300=$A13,"Luisa"&IF('Luisa'!$E$6:$E$300="",""," : "&'Luisa'!$E$6:$E$300)&" ["&'Luisa'!$F$6:$F$300&"]",""),IF('Lui'!$B$6:$B$300=$A13,"Lui"&IF('Lui'!$E$6:$E$300="",""," : "&'Lui'!$E$6:$E$300)&" ["&'Lui'!$F$6:$F$300&"]",""),IF('Thaís'!$B$6:$B$300=$A13,"Thaís"&IF('Thaís'!$E$6:$E$300="",""," : "&'Thaís'!$E$6:$E$300)&" ["&'Thaís'!$F$6:$F$300&"]",""),IF('Daniel'!$B$6:$B$300=$A13,"Daniel"&IF('Daniel'!$E$6:$E$300="",""," : "&'Daniel'!$E$6:$E$300)&" ["&'Daniel'!$F$6:$F$300&"]",""),IF('Fernando'!$B$6:$B$300=$A13,"Fernando"&IF('Fernando'!$E$6:$E$300="",""," : "&'Fernando'!$E$6:$E$300)&" ["&'Fernando'!$F$6:$F$300&"]",""),IF('Stephanie'!$B$6:$B$300=$A13,"Stephanie"&IF('Stephanie'!$E$6:$E$300="",""," : "&'Stephanie'!$E$6:$E$300)&" ["&'Stephanie'!$F$6:$F$300&"]",""),IF('Fox'!$B$6:$B$300=$A13,"Fox"&IF('Fox'!$E$6:$E$300="",""," : "&'Fox'!$E$6:$E$300)&" ["&'Fox'!$F$6:$F$300&"]",""),IF('Bruna'!$B$6:$B$300=$A13,"Bruna"&IF('Bruna'!$E$6:$E$300="",""," : "&'Bruna'!$E$6:$E$300)&" ["&'Bruna'!$F$6:$F$300&"]",""),IF('Stella'!$B$6:$B$300=$A13,"Stella"&IF('Stella'!$E$6:$E$300="",""," : "&'Stella'!$E$6:$E$300)&" ["&'Stella'!$F$6:$F$300&"]",""),IF('Igor'!$B$6:$B$300=$A13,"Igor"&IF('Igor'!$E$6:$E$300="",""," : "&'Igor'!$E$6:$E$300)&" ["&'Igor'!$F$6:$F$300&"]","")))}
A14: ART-007 | B14: Extra - Artigo | C14: 1. Elaboração do artigo sobre a caixa de ferramentas | E14: Envio do artigo para revisão da Bruna | F14: Thaís | G14: =IF($A14="","",_xlfn.TEXTJOIN("; ",TRUE,IF(COUNTIF('Clarice'!$B$6:$B$300,$A14)>0,"Clarice",""),IF(COUNTIF('Luisa'!$B$6:$B$300,$A14)>0,"Luisa",""),IF(COUNTIF('Lui'!$B$6:$B$300,$A14)>0,"Lui",""),IF(COUNTIF('Thaís'!$B$6:$B$300,$A14)>0,"Thaís",""),IF(COUNTIF('Daniel'!$B$6:$B$300,$A14)>0,"Daniel",""),IF(COUNTIF('Fernando'!$B$6:$B$300,$A14)>0,"Fernando",""),IF(COUNTIF('Stephanie'!$B$6:$B$300,$A14)>0,"Stephanie",""),IF(COUNTIF('Fox'!$B$6:$B$300,$A14)>0,"Fox",""),IF(COUNTIF('Bruna'!$B$6:$B$300,$A14)>0,"Bruna",""),IF(COUNTIF('Stella'!$B$6:$B$300,$A14)>0,"Stella",""),IF(COUNTIF('Igor'!$B$6:$B$300,$A14)>0,"Igor",""))) | I14: Concluído | J14: =IF(OR($A14="",(COUNTIF('Clarice'!$B$6:$B$300,$A14)+COUNTIF('Luisa'!$B$6:$B$300,$A14)+COUNTIF('Lui'!$B$6:$B$300,$A14)+COUNTIF('Thaís'!$B$6:$B$300,$A14)+COUNTIF('Daniel'!$B$6:$B$300,$A14)+COUNTIF('Fernando'!$B$6:$B$300,$A14)+COUNTIF('Stephanie'!$B$6:$B$300,$A14)+COUNTIF('Fox'!$B$6:$B$300,$A14)+COUNTIF('Bruna'!$B$6:$B$300,$A14)+COUNTIF('Stella'!$B$6:$B$300,$A14)+COUNTIF('Igor'!$B$6:$B$300,$A14))=0),"",(COUNTIFS('Clarice'!$B$6:$B$300,$A14,'Clarice'!$F$6:$F$300,"Concluído")+COUNTIFS('Luisa'!$B$6:$B$300,$A14,'Luisa'!$F$6:$F$300,"Concluído")+COUNTIFS('Lui'!$B$6:$B$300,$A14,'Lui'!$F$6:$F$300,"Concluído")+COUNTIFS('Thaís'!$B$6:$B$300,$A14,'Thaís'!$F$6:$F$300,"Concluído")+COUNTIFS('Daniel'!$B$6:$B$300,$A14,'Daniel'!$F$6:$F$300,"Concluído")+COUNTIFS('Fernando'!$B$6:$B$300,$A14,'Fernando'!$F$6:$F$300,"Concluído")+COUNTIFS('Stephanie'!$B$6:$B$300,$A14,'Stephanie'!$F$6:$F$300,"Concluído")+COUNTIFS('Fox'!$B$6:$B$300,$A14,'Fox'!$F$6:$F$300,"Concluído")+COUNTIFS('Bruna'!$B$6:$B$300,$A14,'Bruna'!$F$6:$F$300,"Concluído")+COUNTIFS('Stella'!$B$6:$B$300,$A14,'Stella'!$F$6:$F$300,"Concluído")+COUNTIFS('Igor'!$B$6:$B$300,$A14,'Igor'!$F$6:$F$300,"Concluído"))&" / "&(COUNTIF('Clarice'!$B$6:$B$300,$A14)+COUNTIF('Luisa'!$B$6:$B$300,$A14)+COUNTIF('Lui'!$B$6:$B$300,$A14)+COUNTIF('Thaís'!$B$6:$B$300,$A14)+COUNTIF('Daniel'!$B$6:$B$300,$A14)+COUNTIF('Fernando'!$B$6:$B$300,$A14)+COUNTIF('Stephanie'!$B$6:$B$300,$A14)+COUNTIF('Fox'!$B$6:$B$300,$A14)+COUNTIF('Bruna'!$B$6:$B$300,$A14)+COUNTIF('Stella'!$B$6:$B$300,$A14)+COUNTIF('Igor'!$B$6:$B$300,$A14))) | O14: 46129 | P14: =IF($A14="","",IF(M14<>"",M14,IF(K14<>"",K14,""))) | Q14: =IF($A14="","",IF(N14<>"",N14,IF(L14<>"",L14,""))) | S14: {=IF($A14="","",_xlfn.TEXTJOIN(CHAR(10),TRUE,IF('Clarice'!$B$6:$B$300=$A14,"Clarice"&IF('Clarice'!$E$6:$E$300="",""," : "&'Clarice'!$E$6:$E$300)&" ["&'Clarice'!$F$6:$F$300&"]",""),IF('Luisa'!$B$6:$B$300=$A14,"Luisa"&IF('Luisa'!$E$6:$E$300="",""," : "&'Luisa'!$E$6:$E$300)&" ["&'Luisa'!$F$6:$F$300&"]",""),IF('Lui'!$B$6:$B$300=$A14,"Lui"&IF('Lui'!$E$6:$E$300="",""," : "&'Lui'!$E$6:$E$300)&" ["&'Lui'!$F$6:$F$300&"]",""),IF('Thaís'!$B$6:$B$300=$A14,"Thaís"&IF('Thaís'!$E$6:$E$300="",""," : "&'Thaís'!$E$6:$E$300)&" ["&'Thaís'!$F$6:$F$300&"]",""),IF('Daniel'!$B$6:$B$300=$A14,"Daniel"&IF('Daniel'!$E$6:$E$300="",""," : "&'Daniel'!$E$6:$E$300)&" ["&'Daniel'!$F$6:$F$300&"]",""),IF('Fernando'!$B$6:$B$300=$A14,"Fernando"&IF('Fernando'!$E$6:$E$300="",""," : "&'Fernando'!$E$6:$E$300)&" ["&'Fernando'!$F$6:$F$300&"]",""),IF('Stephanie'!$B$6:$B$300=$A14,"Stephanie"&IF('Stephanie'!$E$6:$E$300="",""," : "&'Stephanie'!$E$6:$E$300)&" ["&'Stephanie'!$F$6:$F$300&"]",""),IF('Fox'!$B$6:$B$300=$A14,"Fox"&IF('Fox'!$E$6:$E$300="",""," : "&'Fox'!$E$6:$E$300)&" ["&'Fox'!$F$6:$F$300&"]",""),IF('Bruna'!$B$6:$B$300=$A14,"Bruna"&IF('Bruna'!$E$6:$E$300="",""," : "&'Bruna'!$E$6:$E$300)&" ["&'Bruna'!$F$6:$F$300&"]",""),IF('Stella'!$B$6:$B$300=$A14,"Stella"&IF('Stella'!$E$6:$E$300="",""," : "&'Stella'!$E$6:$E$300)&" ["&'Stella'!$F$6:$F$300&"]",""),IF('Igor'!$B$6:$B$300=$A14,"Igor"&IF('Igor'!$E$6:$E$300="",""," : "&'Igor'!$E$6:$E$300)&" ["&'Igor'!$F$6:$F$300&"]","")))}
A15: ART-008 | B15: Extra - Artigo | C15: 1. Elaboração do artigo sobre a caixa de ferramentas | E15: Revisar possibibilidade de inclusao de métricas de função | F15: Thaís | G15: =IF($A15="","",_xlfn.TEXTJOIN("; ",TRUE,IF(COUNTIF('Clarice'!$B$6:$B$300,$A15)>0,"Clarice",""),IF(COUNTIF('Luisa'!$B$6:$B$300,$A15)>0,"Luisa",""),IF(COUNTIF('Lui'!$B$6:$B$300,$A15)>0,"Lui",""),IF(COUNTIF('Thaís'!$B$6:$B$300,$A15)>0,"Thaís",""),IF(COUNTIF('Daniel'!$B$6:$B$300,$A15)>0,"Daniel",""),IF(COUNTIF('Fernando'!$B$6:$B$300,$A15)>0,"Fernando",""),IF(COUNTIF('Stephanie'!$B$6:$B$300,$A15)>0,"Stephanie",""),IF(COUNTIF('Fox'!$B$6:$B$300,$A15)>0,"Fox",""),IF(COUNTIF('Bruna'!$B$6:$B$300,$A15)>0,"Bruna",""),IF(COUNTIF('Stella'!$B$6:$B$300,$A15)>0,"Stella",""),IF(COUNTIF('Igor'!$B$6:$B$300,$A15)>0,"Igor",""))) | I15: Concluído | J15: =IF(OR($A15="",(COUNTIF('Clarice'!$B$6:$B$300,$A15)+COUNTIF('Luisa'!$B$6:$B$300,$A15)+COUNTIF('Lui'!$B$6:$B$300,$A15)+COUNTIF('Thaís'!$B$6:$B$300,$A15)+COUNTIF('Daniel'!$B$6:$B$300,$A15)+COUNTIF('Fernando'!$B$6:$B$300,$A15)+COUNTIF('Stephanie'!$B$6:$B$300,$A15)+COUNTIF('Fox'!$B$6:$B$300,$A15)+COUNTIF('Bruna'!$B$6:$B$300,$A15)+COUNTIF('Stella'!$B$6:$B$300,$A15)+COUNTIF('Igor'!$B$6:$B$300,$A15))=0),"",(COUNTIFS('Clarice'!$B$6:$B$300,$A15,'Clarice'!$F$6:$F$300,"Concluído")+COUNTIFS('Luisa'!$B$6:$B$300,$A15,'Luisa'!$F$6:$F$300,"Concluído")+COUNTIFS('Lui'!$B$6:$B$300,$A15,'Lui'!$F$6:$F$300,"Concluído")+COUNTIFS('Thaís'!$B$6:$B$300,$A15,'Thaís'!$F$6:$F$300,"Concluído")+COUNTIFS('Daniel'!$B$6:$B$300,$A15,'Daniel'!$F$6:$F$300,"Concluído")+COUNTIFS('Fernando'!$B$6:$B$300,$A15,'Fernando'!$F$6:$F$300,"Concluído")+COUNTIFS('Stephanie'!$B$6:$B$300,$A15,'Stephanie'!$F$6:$F$300,"Concluído")+COUNTIFS('Fox'!$B$6:$B$300,$A15,'Fox'!$F$6:$F$300,"Concluído")+COUNTIFS('Bruna'!$B$6:$B$300,$A15,'Bruna'!$F$6:$F$300,"Concluído")+COUNTIFS('Stella'!$B$6:$B$300,$A15,'Stella'!$F$6:$F$300,"Concluído")+COUNTIFS('Igor'!$B$6:$B$300,$A15,'Igor'!$F$6:$F$300,"Concluído"))&" / "&(COUNTIF('Clarice'!$B$6:$B$300,$A15)+COUNTIF('Luisa'!$B$6:$B$300,$A15)+COUNTIF('Lui'!$B$6:$B$300,$A15)+COUNTIF('Thaís'!$B$6:$B$300,$A15)+COUNTIF('Daniel'!$B$6:$B$300,$A15)+COUNTIF('Fernando'!$B$6:$B$300,$A15)+COUNTIF('Stephanie'!$B$6:$B$300,$A15)+COUNTIF('Fox'!$B$6:$B$300,$A15)+COUNTIF('Bruna'!$B$6:$B$300,$A15)+COUNTIF('Stella'!$B$6:$B$300,$A15)+COUNTIF('Igor'!$B$6:$B$300,$A15))) | M15: 46174 | N15: 46178 | P15: =IF($A15="","",IF(M15<>"",M15,IF(K15<>"",K15,""))) | Q15: =IF($A15="","",IF(N15<>"",N15,IF(L15<>"",L15,""))) | S15: {=IF($A15="","",_xlfn.TEXTJOIN(CHAR(10),TRUE,IF('Clarice'!$B$6:$B$300=$A15,"Clarice"&IF('Clarice'!$E$6:$E$300="",""," : "&'Clarice'!$E$6:$E$300)&" ["&'Clarice'!$F$6:$F$300&"]",""),IF('Luisa'!$B$6:$B$300=$A15,"Luisa"&IF('Luisa'!$E$6:$E$300="",""," : "&'Luisa'!$E$6:$E$300)&" ["&'Luisa'!$F$6:$F$300&"]",""),IF('Lui'!$B$6:$B$300=$A15,"Lui"&IF('Lui'!$E$6:$E$300="",""," : "&'Lui'!$E$6:$E$300)&" ["&'Lui'!$F$6:$F$300&"]",""),IF('Thaís'!$B$6:$B$300=$A15,"Thaís"&IF('Thaís'!$E$6:$E$300="",""," : "&'Thaís'!$E$6:$E$300)&" ["&'Thaís'!$F$6:$F$300&"]",""),IF('Daniel'!$B$6:$B$300=$A15,"Daniel"&IF('Daniel'!$E$6:$E$300="",""," : "&'Daniel'!$E$6:$E$300)&" ["&'Daniel'!$F$6:$F$300&"]",""),IF('Fernando'!$B$6:$B$300=$A15,"Fernando"&IF('Fernando'!$E$6:$E$300="",""," : "&'Fernando'!$E$6:$E$300)&" ["&'Fernando'!$F$6:$F$300&"]",""),IF('Stephanie'!$B$6:$B$300=$A15,"Stephanie"&IF('Stephanie'!$E$6:$E$300="",""," : "&'Stephanie'!$E$6:$E$300)&" ["&'Stephanie'!$F$6:$F$300&"]",""),IF('Fox'!$B$6:$B$300=$A15,"Fox"&IF('Fox'!$E$6:$E$300="",""," : "&'Fox'!$E$6:$E$300)&" ["&'Fox'!$F$6:$F$300&"]",""),IF('Bruna'!$B$6:$B$300=$A15,"Bruna"&IF('Bruna'!$E$6:$E$300="",""," : "&'Bruna'!$E$6:$E$300)&" ["&'Bruna'!$F$6:$F$300&"]",""),IF('Stella'!$B$6:$B$300=$A15,"Stella"&IF('Stella'!$E$6:$E$300="",""," : "&'Stella'!$E$6:$E$300)&" ["&'Stella'!$F$6:$F$300&"]",""),IF('Igor'!$B$6:$B$300=$A15,"Igor"&IF('Igor'!$E$6:$E$300="",""," : "&'Igor'!$E$6:$E$300)&" ["&'Igor'!$F$6:$F$300&"]","")))}
A16: ART-009 | B16: Extra - Artigo | C16: 1. Elaboração do artigo sobre a caixa de ferramentas | E16: Definir a revista | F16: Thaís | G16: =IF($A16="","",_xlfn.TEXTJOIN("; ",TRUE,IF(COUNTIF('Clarice'!$B$6:$B$300,$A16)>0,"Clarice",""),IF(COUNTIF('Luisa'!$B$6:$B$300,$A16)>0,"Luisa",""),IF(COUNTIF('Lui'!$B$6:$B$300,$A16)>0,"Lui",""),IF(COUNTIF('Thaís'!$B$6:$B$300,$A16)>0,"Thaís",""),IF(COUNTIF('Daniel'!$B$6:$B$300,$A16)>0,"Daniel",""),IF(COUNTIF('Fernando'!$B$6:$B$300,$A16)>0,"Fernando",""),IF(COUNTIF('Stephanie'!$B$6:$B$300,$A16)>0,"Stephanie",""),IF(COUNTIF('Fox'!$B$6:$B$300,$A16)>0,"Fox",""),IF(COUNTIF('Bruna'!$B$6:$B$300,$A16)>0,"Bruna",""),IF(COUNTIF('Stella'!$B$6:$B$300,$A16)>0,"Stella",""),IF(COUNTIF('Igor'!$B$6:$B$300,$A16)>0,"Igor",""))) | H16: Petrobras | I16: Concluído | J16: =IF(OR($A16="",(COUNTIF('Clarice'!$B$6:$B$300,$A16)+COUNTIF('Luisa'!$B$6:$B$300,$A16)+COUNTIF('Lui'!$B$6:$B$300,$A16)+COUNTIF('Thaís'!$B$6:$B$300,$A16)+COUNTIF('Daniel'!$B$6:$B$300,$A16)+COUNTIF('Fernando'!$B$6:$B$300,$A16)+COUNTIF('Stephanie'!$B$6:$B$300,$A16)+COUNTIF('Fox'!$B$6:$B$300,$A16)+COUNTIF('Bruna'!$B$6:$B$300,$A16)+COUNTIF('Stella'!$B$6:$B$300,$A16)+COUNTIF('Igor'!$B$6:$B$300,$A16))=0),"",(COUNTIFS('Clarice'!$B$6:$B$300,$A16,'Clarice'!$F$6:$F$300,"Concluído")+COUNTIFS('Luisa'!$B$6:$B$300,$A16,'Luisa'!$F$6:$F$300,"Concluído")+COUNTIFS('Lui'!$B$6:$B$300,$A16,'Lui'!$F$6:$F$300,"Concluído")+COUNTIFS('Thaís'!$B$6:$B$300,$A16,'Thaís'!$F$6:$F$300,"Concluído")+COUNTIFS('Daniel'!$B$6:$B$300,$A16,'Daniel'!$F$6:$F$300,"Concluído")+COUNTIFS('Fernando'!$B$6:$B$300,$A16,'Fernando'!$F$6:$F$300,"Concluído")+COUNTIFS('Stephanie'!$B$6:$B$300,$A16,'Stephanie'!$F$6:$F$300,"Concluído")+COUNTIFS('Fox'!$B$6:$B$300,$A16,'Fox'!$F$6:$F$300,"Concluído")+COUNTIFS('Bruna'!$B$6:$B$300,$A16,'Bruna'!$F$6:$F$300,"Concluído")+COUNTIFS('Stella'!$B$6:$B$300,$A16,'Stella'!$F$6:$F$300,"Concluído")+COUNTIFS('Igor'!$B$6:$B$300,$A16,'Igor'!$F$6:$F$300,"Concluído"))&" / "&(COUNTIF('Clarice'!$B$6:$B$300,$A16)+COUNTIF('Luisa'!$B$6:$B$300,$A16)+COUNTIF('Lui'!$B$6:$B$300,$A16)+COUNTIF('Thaís'!$B$6:$B$300,$A16)+COUNTIF('Daniel'!$B$6:$B$300,$A16)+COUNTIF('Fernando'!$B$6:$B$300,$A16)+COUNTIF('Stephanie'!$B$6:$B$300,$A16)+COUNTIF('Fox'!$B$6:$B$300,$A16)+COUNTIF('Bruna'!$B$6:$B$300,$A16)+COUNTIF('Stella'!$B$6:$B$300,$A16)+COUNTIF('Igor'!$B$6:$B$300,$A16))) | K16: 46153 | L16: 46157 | M16: 46153 | N16: 46185 | P16: =IF($A16="","",IF(M16<>"",M16,IF(K16<>"",K16,""))) | Q16: =IF($A16="","",IF(N16<>"",N16,IF(L16<>"",L16,""))) | S16: {=IF($A16="","",_xlfn.TEXTJOIN(CHAR(10),TRUE,IF('Clarice'!$B$6:$B$300=$A16,"Clarice"&IF('Clarice'!$E$6:$E$300="",""," : "&'Clarice'!$E$6:$E$300)&" ["&'Clarice'!$F$6:$F$300&"]",""),IF('Luisa'!$B$6:$B$300=$A16,"Luisa"&IF('Luisa'!$E$6:$E$300="",""," : "&'Luisa'!$E$6:$E$300)&" ["&'Luisa'!$F$6:$F$300&"]",""),IF('Lui'!$B$6:$B$300=$A16,"Lui"&IF('Lui'!$E$6:$E$300="",""," : "&'Lui'!$E$6:$E$300)&" ["&'Lui'!$F$6:$F$300&"]",""),IF('Thaís'!$B$6:$B$300=$A16,"Thaís"&IF('Thaís'!$E$6:$E$300="",""," : "&'Thaís'!$E$6:$E$300)&" ["&'Thaís'!$F$6:$F$300&"]",""),IF('Daniel'!$B$6:$B$300=$A16,"Daniel"&IF('Daniel'!$E$6:$E$300="",""," : "&'Daniel'!$E$6:$E$300)&" ["&'Daniel'!$F$6:$F$300&"]",""),IF('Fernando'!$B$6:$B$300=$A16,"Fernando"&IF('Fernando'!$E$6:$E$300="",""," : "&'Fernando'!$E$6:$E$300)&" ["&'Fernando'!$F$6:$F$300&"]",""),IF('Stephanie'!$B$6:$B$300=$A16,"Stephanie"&IF('Stephanie'!$E$6:$E$300="",""," : "&'Stephanie'!$E$6:$E$300)&" ["&'Stephanie'!$F$6:$F$300&"]",""),IF('Fox'!$B$6:$B$300=$A16,"Fox"&IF('Fox'!$E$6:$E$300="",""," : "&'Fox'!$E$6:$E$300)&" ["&'Fox'!$F$6:$F$300&"]",""),IF('Bruna'!$B$6:$B$300=$A16,"Bruna"&IF('Bruna'!$E$6:$E$300="",""," : "&'Bruna'!$E$6:$E$300)&" ["&'Bruna'!$F$6:$F$300&"]",""),IF('Stella'!$B$6:$B$300=$A16,"Stella"&IF('Stella'!$E$6:$E$300="",""," : "&'Stella'!$E$6:$E$300)&" ["&'Stella'!$F$6:$F$300&"]",""),IF('Igor'!$B$6:$B$300=$A16,"Igor"&IF('Igor'!$E$6:$E$300="",""," : "&'Igor'!$E$6:$E$300)&" ["&'Igor'!$F$6:$F$300&"]","")))}
A17: ART-010 | B17: Extra - Artigo | C17: 1. Elaboração do artigo sobre a caixa de ferramentas | E17: Formatar artigo para a revista | F17: Thaís | G17: =IF($A17="","",_xlfn.TEXTJOIN("; ",TRUE,IF(COUNTIF('Clarice'!$B$6:$B$300,$A17)>0,"Clarice",""),IF(COUNTIF('Luisa'!$B$6:$B$300,$A17)>0,"Luisa",""),IF(COUNTIF('Lui'!$B$6:$B$300,$A17)>0,"Lui",""),IF(COUNTIF('Thaís'!$B$6:$B$300,$A17)>0,"Thaís",""),IF(COUNTIF('Daniel'!$B$6:$B$300,$A17)>0,"Daniel",""),IF(COUNTIF('Fernando'!$B$6:$B$300,$A17)>0,"Fernando",""),IF(COUNTIF('Stephanie'!$B$6:$B$300,$A17)>0,"Stephanie",""),IF(COUNTIF('Fox'!$B$6:$B$300,$A17)>0,"Fox",""),IF(COUNTIF('Bruna'!$B$6:$B$300,$A17)>0,"Bruna",""),IF(COUNTIF('Stella'!$B$6:$B$300,$A17)>0,"Stella",""),IF(COUNTIF('Igor'!$B$6:$B$300,$A17)>0,"Igor",""))) | I17: Concluído | J17: =IF(OR($A17="",(COUNTIF('Clarice'!$B$6:$B$300,$A17)+COUNTIF('Luisa'!$B$6:$B$300,$A17)+COUNTIF('Lui'!$B$6:$B$300,$A17)+COUNTIF('Thaís'!$B$6:$B$300,$A17)+COUNTIF('Daniel'!$B$6:$B$300,$A17)+COUNTIF('Fernando'!$B$6:$B$300,$A17)+COUNTIF('Stephanie'!$B$6:$B$300,$A17)+COUNTIF('Fox'!$B$6:$B$300,$A17)+COUNTIF('Bruna'!$B$6:$B$300,$A17)+COUNTIF('Stella'!$B$6:$B$300,$A17)+COUNTIF('Igor'!$B$6:$B$300,$A17))=0),"",(COUNTIFS('Clarice'!$B$6:$B$300,$A17,'Clarice'!$F$6:$F$300,"Concluído")+COUNTIFS('Luisa'!$B$6:$B$300,$A17,'Luisa'!$F$6:$F$300,"Concluído")+COUNTIFS('Lui'!$B$6:$B$300,$A17,'Lui'!$F$6:$F$300,"Concluído")+COUNTIFS('Thaís'!$B$6:$B$300,$A17,'Thaís'!$F$6:$F$300,"Concluído")+COUNTIFS('Daniel'!$B$6:$B$300,$A17,'Daniel'!$F$6:$F$300,"Concluído")+COUNTIFS('Fernando'!$B$6:$B$300,$A17,'Fernando'!$F$6:$F$300,"Concluído")+COUNTIFS('Stephanie'!$B$6:$B$300,$A17,'Stephanie'!$F$6:$F$300,"Concluído")+COUNTIFS('Fox'!$B$6:$B$300,$A17,'Fox'!$F$6:$F$300,"Concluído")+COUNTIFS('Bruna'!$B$6:$B$300,$A17,'Bruna'!$F$6:$F$300,"Concluído")+COUNTIFS('Stella'!$B$6:$B$300,$A17,'Stella'!$F$6:$F$300,"Concluído")+COUNTIFS('Igor'!$B$6:$B$300,$A17,'Igor'!$F$6:$F$300,"Concluído"))&" / "&(COUNTIF('Clarice'!$B$6:$B$300,$A17)+COUNTIF('Luisa'!$B$6:$B$300,$A17)+COUNTIF('Lui'!$B$6:$B$300,$A17)+COUNTIF('Thaís'!$B$6:$B$300,$A17)+COUNTIF('Daniel'!$B$6:$B$300,$A17)+COUNTIF('Fernando'!$B$6:$B$300,$A17)+COUNTIF('Stephanie'!$B$6:$B$300,$A17)+COUNTIF('Fox'!$B$6:$B$300,$A17)+COUNTIF('Bruna'!$B$6:$B$300,$A17)+COUNTIF('Stella'!$B$6:$B$300,$A17)+COUNTIF('Igor'!$B$6:$B$300,$A17))) | K17: 46167 | L17: 46171 | M17: 46167 | N17: 46220 | P17: =IF($A17="","",IF(M17<>"",M17,IF(K17<>"",K17,""))) | Q17: =IF($A17="","",IF(N17<>"",N17,IF(L17<>"",L17,""))) | S17: {=IF($A17="","",_xlfn.TEXTJOIN(CHAR(10),TRUE,IF('Clarice'!$B$6:$B$300=$A17,"Clarice"&IF('Clarice'!$E$6:$E$300="",""," : "&'Clarice'!$E$6:$E$300)&" ["&'Clarice'!$F$6:$F$300&"]",""),IF('Luisa'!$B$6:$B$300=$A17,"Luisa"&IF('Luisa'!$E$6:$E$300="",""," : "&'Luisa'!$E$6:$E$300)&" ["&'Luisa'!$F$6:$F$300&"]",""),IF('Lui'!$B$6:$B$300=$A17,"Lui"&IF('Lui'!$E$6:$E$300="",""," : "&'Lui'!$E$6:$E$300)&" ["&'Lui'!$F$6:$F$300&"]",""),IF('Thaís'!$B$6:$B$300=$A17,"Thaís"&IF('Thaís'!$E$6:$E$300="",""," : "&'Thaís'!$E$6:$E$300)&" ["&'Thaís'!$F$6:$F$300&"]",""),IF('Daniel'!$B$6:$B$300=$A17,"Daniel"&IF('Daniel'!$E$6:$E$300="",""," : "&'Daniel'!$E$6:$E$300)&" ["&'Daniel'!$F$6:$F$300&"]",""),IF('Fernando'!$B$6:$B$300=$A17,"Fernando"&IF('Fernando'!$E$6:$E$300="",""," : "&'Fernando'!$E$6:$E$300)&" ["&'Fernando'!$F$6:$F$300&"]",""),IF('Stephanie'!$B$6:$B$300=$A17,"Stephanie"&IF('Stephanie'!$E$6:$E$300="",""," : "&'Stephanie'!$E$6:$E$300)&" ["&'Stephanie'!$F$6:$F$300&"]",""),IF('Fox'!$B$6:$B$300=$A17,"Fox"&IF('Fox'!$E$6:$E$300="",""," : "&'Fox'!$E$6:$E$300)&" ["&'Fox'!$F$6:$F$300&"]",""),IF('Bruna'!$B$6:$B$300=$A17,"Bruna"&IF('Bruna'!$E$6:$E$300="",""," : "&'Bruna'!$E$6:$E$300)&" ["&'Bruna'!$F$6:$F$300&"]",""),IF('Stella'!$B$6:$B$300=$A17,"Stella"&IF('Stella'!$E$6:$E$300="",""," : "&'Stella'!$E$6:$E$300)&" ["&'Stella'!$F$6:$F$300&"]",""),IF('Igor'!$B$6:$B$300=$A17,"Igor"&IF('Igor'!$E$6:$E$300="",""," : "&'Igor'!$E$6:$E$300)&" ["&'Igor'!$F$6:$F$300&"]","")))}
A18: ART-011 | B18: Extra - Artigo | C18: 1. Elaboração do artigo sobre a caixa de ferramentas | E18: Revisão Bruna | F18: Thaís | G18: =IF($A18="","",_xlfn.TEXTJOIN("; ",TRUE,IF(COUNTIF('Clarice'!$B$6:$B$300,$A18)>0,"Clarice",""),IF(COUNTIF('Luisa'!$B$6:$B$300,$A18)>0,"Luisa",""),IF(COUNTIF('Lui'!$B$6:$B$300,$A18)>0,"Lui",""),IF(COUNTIF('Thaís'!$B$6:$B$300,$A18)>0,"Thaís",""),IF(COUNTIF('Daniel'!$B$6:$B$300,$A18)>0,"Daniel",""),IF(COUNTIF('Fernando'!$B$6:$B$300,$A18)>0,"Fernando",""),IF(COUNTIF('Stephanie'!$B$6:$B$300,$A18)>0,"Stephanie",""),IF(COUNTIF('Fox'!$B$6:$B$300,$A18)>0,"Fox",""),IF(COUNTIF('Bruna'!$B$6:$B$300,$A18)>0,"Bruna",""),IF(COUNTIF('Stella'!$B$6:$B$300,$A18)>0,"Stella",""),IF(COUNTIF('Igor'!$B$6:$B$300,$A18)>0,"Igor",""))) | I18: Concluído | J18: =IF(OR($A18="",(COUNTIF('Clarice'!$B$6:$B$300,$A18)+COUNTIF('Luisa'!$B$6:$B$300,$A18)+COUNTIF('Lui'!$B$6:$B$300,$A18)+COUNTIF('Thaís'!$B$6:$B$300,$A18)+COUNTIF('Daniel'!$B$6:$B$300,$A18)+COUNTIF('Fernando'!$B$6:$B$300,$A18)+COUNTIF('Stephanie'!$B$6:$B$300,$A18)+COUNTIF('Fox'!$B$6:$B$300,$A18)+COUNTIF('Bruna'!$B$6:$B$300,$A18)+COUNTIF('Stella'!$B$6:$B$300,$A18)+COUNTIF('Igor'!$B$6:$B$300,$A18))=0),"",(COUNTIFS('Clarice'!$B$6:$B$300,$A18,'Clarice'!$F$6:$F$300,"Concluído")+COUNTIFS('Luisa'!$B$6:$B$300,$A18,'Luisa'!$F$6:$F$300,"Concluído")+COUNTIFS('Lui'!$B$6:$B$300,$A18,'Lui'!$F$6:$F$300,"Concluído")+COUNTIFS('Thaís'!$B$6:$B$300,$A18,'Thaís'!$F$6:$F$300,"Concluído")+COUNTIFS('Daniel'!$B$6:$B$300,$A18,'Daniel'!$F$6:$F$300,"Concluído")+COUNTIFS('Fernando'!$B$6:$B$300,$A18,'Fernando'!$F$6:$F$300,"Concluído")+COUNTIFS('Stephanie'!$B$6:$B$300,$A18,'Stephanie'!$F$6:$F$300,"Concluído")+COUNTIFS('Fox'!$B$6:$B$300,$A18,'Fox'!$F$6:$F$300,"Concluído")+COUNTIFS('Bruna'!$B$6:$B$300,$A18,'Bruna'!$F$6:$F$300,"Concluído")+COUNTIFS('Stella'!$B$6:$B$300,$A18,'Stella'!$F$6:$F$300,"Concluído")+COUNTIFS('Igor'!$B$6:$B$300,$A18,'Igor'!$F$6:$F$300,"Concluído"))&" / "&(COUNTIF('Clarice'!$B$6:$B$300,$A18)+COUNTIF('Luisa'!$B$6:$B$300,$A18)+COUNTIF('Lui'!$B$6:$B$300,$A18)+COUNTIF('Thaís'!$B$6:$B$300,$A18)+COUNTIF('Daniel'!$B$6:$B$300,$A18)+COUNTIF('Fernando'!$B$6:$B$300,$A18)+COUNTIF('Stephanie'!$B$6:$B$300,$A18)+COUNTIF('Fox'!$B$6:$B$300,$A18)+COUNTIF('Bruna'!$B$6:$B$300,$A18)+COUNTIF('Stella'!$B$6:$B$300,$A18)+COUNTIF('Igor'!$B$6:$B$300,$A18))) | K18: 46132 | L18: 46142 | M18: 46132 | N18: 46199 | P18: =IF($A18="","",IF(M18<>"",M18,IF(K18<>"",K18,""))) | Q18: =IF($A18="","",IF(N18<>"",N18,IF(L18<>"",L18,""))) | S18: {=IF($A18="","",_xlfn.TEXTJOIN(CHAR(10),TRUE,IF('Clarice'!$B$6:$B$300=$A18,"Clarice"&IF('Clarice'!$E$6:$E$300="",""," : "&'Clarice'!$E$6:$E$300)&" ["&'Clarice'!$F$6:$F$300&"]",""),IF('Luisa'!$B$6:$B$300=$A18,"Luisa"&IF('Luisa'!$E$6:$E$300="",""," : "&'Luisa'!$E$6:$E$300)&" ["&'Luisa'!$F$6:$F$300&"]",""),IF('Lui'!$B$6:$B$300=$A18,"Lui"&IF('Lui'!$E$6:$E$300="",""," : "&'Lui'!$E$6:$E$300)&" ["&'Lui'!$F$6:$F$300&"]",""),IF('Thaís'!$B$6:$B$300=$A18,"Thaís"&IF('Thaís'!$E$6:$E$300="",""," : "&'Thaís'!$E$6:$E$300)&" ["&'Thaís'!$F$6:$F$300&"]",""),IF('Daniel'!$B$6:$B$300=$A18,"Daniel"&IF('Daniel'!$E$6:$E$300="",""," : "&'Daniel'!$E$6:$E$300)&" ["&'Daniel'!$F$6:$F$300&"]",""),IF('Fernando'!$B$6:$B$300=$A18,"Fernando"&IF('Fernando'!$E$6:$E$300="",""," : "&'Fernando'!$E$6:$E$300)&" ["&'Fernando'!$F$6:$F$300&"]",""),IF('Stephanie'!$B$6:$B$300=$A18,"Stephanie"&IF('Stephanie'!$E$6:$E$300="",""," : "&'Stephanie'!$E$6:$E$300)&" ["&'Stephanie'!$F$6:$F$300&"]",""),IF('Fox'!$B$6:$B$300=$A18,"Fox"&IF('Fox'!$E$6:$E$300="",""," : "&'Fox'!$E$6:$E$300)&" ["&'Fox'!$F$6:$F$300&"]",""),IF('Bruna'!$B$6:$B$300=$A18,"Bruna"&IF('Bruna'!$E$6:$E$300="",""," : "&'Bruna'!$E$6:$E$300)&" ["&'Bruna'!$F$6:$F$300&"]",""),IF('Stella'!$B$6:$B$300=$A18,"Stella"&IF('Stella'!$E$6:$E$300="",""," : "&'Stella'!$E$6:$E$300)&" ["&'Stella'!$F$6:$F$300&"]",""),IF('Igor'!$B$6:$B$300=$A18,"Igor"&IF('Igor'!$E$6:$E$300="",""," : "&'Igor'!$E$6:$E$300)&" ["&'Igor'!$F$6:$F$300&"]","")))}
A19: ART-012 | B19: Extra - Artigo | C19: 1. Elaboração do artigo sobre a caixa de ferramentas | E19: Incorporar os ajustes da Bruna | F19: Thaís | G19: =IF($A19="","",_xlfn.TEXTJOIN("; ",TRUE,IF(COUNTIF('Clarice'!$B$6:$B$300,$A19)>0,"Clarice",""),IF(COUNTIF('Luisa'!$B$6:$B$300,$A19)>0,"Luisa",""),IF(COUNTIF('Lui'!$B$6:$B$300,$A19)>0,"Lui",""),IF(COUNTIF('Thaís'!$B$6:$B$300,$A19)>0,"Thaís",""),IF(COUNTIF('Daniel'!$B$6:$B$300,$A19)>0,"Daniel",""),IF(COUNTIF('Fernando'!$B$6:$B$300,$A19)>0,"Fernando",""),IF(COUNTIF('Stephanie'!$B$6:$B$300,$A19)>0,"Stephanie",""),IF(COUNTIF('Fox'!$B$6:$B$300,$A19)>0,"Fox",""),IF(COUNTIF('Bruna'!$B$6:$B$300,$A19)>0,"Bruna",""),IF(COUNTIF('Stella'!$B$6:$B$300,$A19)>0,"Stella",""),IF(COUNTIF('Igor'!$B$6:$B$300,$A19)>0,"Igor",""))) | I19: Concluído | J19: =IF(OR($A19="",(COUNTIF('Clarice'!$B$6:$B$300,$A19)+COUNTIF('Luisa'!$B$6:$B$300,$A19)+COUNTIF('Lui'!$B$6:$B$300,$A19)+COUNTIF('Thaís'!$B$6:$B$300,$A19)+COUNTIF('Daniel'!$B$6:$B$300,$A19)+COUNTIF('Fernando'!$B$6:$B$300,$A19)+COUNTIF('Stephanie'!$B$6:$B$300,$A19)+COUNTIF('Fox'!$B$6:$B$300,$A19)+COUNTIF('Bruna'!$B$6:$B$300,$A19)+COUNTIF('Stella'!$B$6:$B$300,$A19)+COUNTIF('Igor'!$B$6:$B$300,$A19))=0),"",(COUNTIFS('Clarice'!$B$6:$B$300,$A19,'Clarice'!$F$6:$F$300,"Concluído")+COUNTIFS('Luisa'!$B$6:$B$300,$A19,'Luisa'!$F$6:$F$300,"Concluído")+COUNTIFS('Lui'!$B$6:$B$300,$A19,'Lui'!$F$6:$F$300,"Concluído")+COUNTIFS('Thaís'!$B$6:$B$300,$A19,'Thaís'!$F$6:$F$300,"Concluído")+COUNTIFS('Daniel'!$B$6:$B$300,$A19,'Daniel'!$F$6:$F$300,"Concluído")+COUNTIFS('Fernando'!$B$6:$B$300,$A19,'Fernando'!$F$6:$F$300,"Concluído")+COUNTIFS('Stephanie'!$B$6:$B$300,$A19,'Stephanie'!$F$6:$F$300,"Concluído")+COUNTIFS('Fox'!$B$6:$B$300,$A19,'Fox'!$F$6:$F$300,"Concluído")+COUNTIFS('Bruna'!$B$6:$B$300,$A19,'Bruna'!$F$6:$F$300,"Concluído")+COUNTIFS('Stella'!$B$6:$B$300,$A19,'Stella'!$F$6:$F$300,"Concluído")+COUNTIFS('Igor'!$B$6:$B$300,$A19,'Igor'!$F$6:$F$300,"Concluído"))&" / "&(COUNTIF('Clarice'!$B$6:$B$300,$A19)+COUNTIF('Luisa'!$B$6:$B$300,$A19)+COUNTIF('Lui'!$B$6:$B$300,$A19)+COUNTIF('Thaís'!$B$6:$B$300,$A19)+COUNTIF('Daniel'!$B$6:$B$300,$A19)+COUNTIF('Fernando'!$B$6:$B$300,$A19)+COUNTIF('Stephanie'!$B$6:$B$300,$A19)+COUNTIF('Fox'!$B$6:$B$300,$A19)+COUNTIF('Bruna'!$B$6:$B$300,$A19)+COUNTIF('Stella'!$B$6:$B$300,$A19)+COUNTIF('Igor'!$B$6:$B$300,$A19))) | M19: 46202 | N19: 46206 | P19: =IF($A19="","",IF(M19<>"",M19,IF(K19<>"",K19,""))) | Q19: =IF($A19="","",IF(N19<>"",N19,IF(L19<>"",L19,""))) | S19: {=IF($A19="","",_xlfn.TEXTJOIN(CHAR(10),TRUE,IF('Clarice'!$B$6:$B$300=$A19,"Clarice"&IF('Clarice'!$E$6:$E$300="",""," : "&'Clarice'!$E$6:$E$300)&" ["&'Clarice'!$F$6:$F$300&"]",""),IF('Luisa'!$B$6:$B$300=$A19,"Luisa"&IF('Luisa'!$E$6:$E$300="",""," : "&'Luisa'!$E$6:$E$300)&" ["&'Luisa'!$F$6:$F$300&"]",""),IF('Lui'!$B$6:$B$300=$A19,"Lui"&IF('Lui'!$E$6:$E$300="",""," : "&'Lui'!$E$6:$E$300)&" ["&'Lui'!$F$6:$F$300&"]",""),IF('Thaís'!$B$6:$B$300=$A19,"Thaís"&IF('Thaís'!$E$6:$E$300="",""," : "&'Thaís'!$E$6:$E$300)&" ["&'Thaís'!$F$6:$F$300&"]",""),IF('Daniel'!$B$6:$B$300=$A19,"Daniel"&IF('Daniel'!$E$6:$E$300="",""," : "&'Daniel'!$E$6:$E$300)&" ["&'Daniel'!$F$6:$F$300&"]",""),IF('Fernando'!$B$6:$B$300=$A19,"Fernando"&IF('Fernando'!$E$6:$E$300="",""," : "&'Fernando'!$E$6:$E$300)&" ["&'Fernando'!$F$6:$F$300&"]",""),IF('Stephanie'!$B$6:$B$300=$A19,"Stephanie"&IF('Stephanie'!$E$6:$E$300="",""," : "&'Stephanie'!$E$6:$E$300)&" ["&'Stephanie'!$F$6:$F$300&"]",""),IF('Fox'!$B$6:$B$300=$A19,"Fox"&IF('Fox'!$E$6:$E$300="",""," : "&'Fox'!$E$6:$E$300)&" ["&'Fox'!$F$6:$F$300&"]",""),IF('Bruna'!$B$6:$B$300=$A19,"Bruna"&IF('Bruna'!$E$6:$E$300="",""," : "&'Bruna'!$E$6:$E$300)&" ["&'Bruna'!$F$6:$F$300&"]",""),IF('Stella'!$B$6:$B$300=$A19,"Stella"&IF('Stella'!$E$6:$E$300="",""," : "&'Stella'!$E$6:$E$300)&" ["&'Stella'!$F$6:$F$300&"]",""),IF('Igor'!$B$6:$B$300=$A19,"Igor"&IF('Igor'!$E$6:$E$300="",""," : "&'Igor'!$E$6:$E$300)&" ["&'Igor'!$F$6:$F$300&"]","")))}
A20: ART-013 | B20: Extra - Artigo | C20: 1. Elaboração do artigo sobre a caixa de ferramentas | E20: Envio do artigo para revisão da Petrobras | F20: Thaís | G20: =IF($A20="","",_xlfn.TEXTJOIN("; ",TRUE,IF(COUNTIF('Clarice'!$B$6:$B$300,$A20)>0,"Clarice",""),IF(COUNTIF('Luisa'!$B$6:$B$300,$A20)>0,"Luisa",""),IF(COUNTIF('Lui'!$B$6:$B$300,$A20)>0,"Lui",""),IF(COUNTIF('Thaís'!$B$6:$B$300,$A20)>0,"Thaís",""),IF(COUNTIF('Daniel'!$B$6:$B$300,$A20)>0,"Daniel",""),IF(COUNTIF('Fernando'!$B$6:$B$300,$A20)>0,"Fernando",""),IF(COUNTIF('Stephanie'!$B$6:$B$300,$A20)>0,"Stephanie",""),IF(COUNTIF('Fox'!$B$6:$B$300,$A20)>0,"Fox",""),IF(COUNTIF('Bruna'!$B$6:$B$300,$A20)>0,"Bruna",""),IF(COUNTIF('Stella'!$B$6:$B$300,$A20)>0,"Stella",""),IF(COUNTIF('Igor'!$B$6:$B$300,$A20)>0,"Igor",""))) | I20: Concluído | J20: =IF(OR($A20="",(COUNTIF('Clarice'!$B$6:$B$300,$A20)+COUNTIF('Luisa'!$B$6:$B$300,$A20)+COUNTIF('Lui'!$B$6:$B$300,$A20)+COUNTIF('Thaís'!$B$6:$B$300,$A20)+COUNTIF('Daniel'!$B$6:$B$300,$A20)+COUNTIF('Fernando'!$B$6:$B$300,$A20)+COUNTIF('Stephanie'!$B$6:$B$300,$A20)+COUNTIF('Fox'!$B$6:$B$300,$A20)+COUNTIF('Bruna'!$B$6:$B$300,$A20)+COUNTIF('Stella'!$B$6:$B$300,$A20)+COUNTIF('Igor'!$B$6:$B$300,$A20))=0),"",(COUNTIFS('Clarice'!$B$6:$B$300,$A20,'Clarice'!$F$6:$F$300,"Concluído")+COUNTIFS('Luisa'!$B$6:$B$300,$A20,'Luisa'!$F$6:$F$300,"Concluído")+COUNTIFS('Lui'!$B$6:$B$300,$A20,'Lui'!$F$6:$F$300,"Concluído")+COUNTIFS('Thaís'!$B$6:$B$300,$A20,'Thaís'!$F$6:$F$300,"Concluído")+COUNTIFS('Daniel'!$B$6:$B$300,$A20,'Daniel'!$F$6:$F$300,"Concluído")+COUNTIFS('Fernando'!$B$6:$B$300,$A20,'Fernando'!$F$6:$F$300,"Concluído")+COUNTIFS('Stephanie'!$B$6:$B$300,$A20,'Stephanie'!$F$6:$F$300,"Concluído")+COUNTIFS('Fox'!$B$6:$B$300,$A20,'Fox'!$F$6:$F$300,"Concluído")+COUNTIFS('Bruna'!$B$6:$B$300,$A20,'Bruna'!$F$6:$F$300,"Concluído")+COUNTIFS('Stella'!$B$6:$B$300,$A20,'Stella'!$F$6:$F$300,"Concluído")+COUNTIFS('Igor'!$B$6:$B$300,$A20,'Igor'!$F$6:$F$300,"Concluído"))&" / "&(COUNTIF('Clarice'!$B$6:$B$300,$A20)+COUNTIF('Luisa'!$B$6:$B$300,$A20)+COUNTIF('Lui'!$B$6:$B$300,$A20)+COUNTIF('Thaís'!$B$6:$B$300,$A20)+COUNTIF('Daniel'!$B$6:$B$300,$A20)+COUNTIF('Fernando'!$B$6:$B$300,$A20)+COUNTIF('Stephanie'!$B$6:$B$300,$A20)+COUNTIF('Fox'!$B$6:$B$300,$A20)+COUNTIF('Bruna'!$B$6:$B$300,$A20)+COUNTIF('Stella'!$B$6:$B$300,$A20)+COUNTIF('Igor'!$B$6:$B$300,$A20))) | K20: 46181 | L20: 46185 | M20: 46181 | N20: 46213 | P20: =IF($A20="","",IF(M20<>"",M20,IF(K20<>"",K20,""))) | Q20: =IF($A20="","",IF(N20<>"",N20,IF(L20<>"",L20,""))) | S20: {=IF($A20="","",_xlfn.TEXTJOIN(CHAR(10),TRUE,IF('Clarice'!$B$6:$B$300=$A20,"Clarice"&IF('Clarice'!$E$6:$E$300="",""," : "&'Clarice'!$E$6:$E$300)&" ["&'Clarice'!$F$6:$F$300&"]",""),IF('Luisa'!$B$6:$B$300=$A20,"Luisa"&IF('Luisa'!$E$6:$E$300="",""," : "&'Luisa'!$E$6:$E$300)&" ["&'Luisa'!$F$6:$F$300&"]",""),IF('Lui'!$B$6:$B$300=$A20,"Lui"&IF('Lui'!$E$6:$E$300="",""," : "&'Lui'!$E$6:$E$300)&" ["&'Lui'!$F$6:$F$300&"]",""),IF('Thaís'!$B$6:$B$300=$A20,"Thaís"&IF('Thaís'!$E$6:$E$300="",""," : "&'Thaís'!$E$6:$E$300)&" ["&'Thaís'!$F$6:$F$300&"]",""),IF('Daniel'!$B$6:$B$300=$A20,"Daniel"&IF('Daniel'!$E$6:$E$300="",""," : "&'Daniel'!$E$6:$E$300)&" ["&'Daniel'!$F$6:$F$300&"]",""),IF('Fernando'!$B$6:$B$300=$A20,"Fernando"&IF('Fernando'!$E$6:$E$300="",""," : "&'Fernando'!$E$6:$E$300)&" ["&'Fernando'!$F$6:$F$300&"]",""),IF('Stephanie'!$B$6:$B$300=$A20,"Stephanie"&IF('Stephanie'!$E$6:$E$300="",""," : "&'Stephanie'!$E$6:$E$300)&" ["&'Stephanie'!$F$6:$F$300&"]",""),IF('Fox'!$B$6:$B$300=$A20,"Fox"&IF('Fox'!$E$6:$E$300="",""," : "&'Fox'!$E$6:$E$300)&" ["&'Fox'!$F$6:$F$300&"]",""),IF('Bruna'!$B$6:$B$300=$A20,"Bruna"&IF('Bruna'!$E$6:$E$300="",""," : "&'Bruna'!$E$6:$E$300)&" ["&'Bruna'!$F$6:$F$300&"]",""),IF('Stella'!$B$6:$B$300=$A20,"Stella"&IF('Stella'!$E$6:$E$300="",""," : "&'Stella'!$E$6:$E$300)&" ["&'Stella'!$F$6:$F$300&"]",""),IF('Igor'!$B$6:$B$300=$A20,"Igor"&IF('Igor'!$E$6:$E$300="",""," : "&'Igor'!$E$6:$E$300)&" ["&'Igor'!$F$6:$F$300&"]","")))}
